Workbook
Name DOLARIN: [1]ANALISIS!$H$2
Name ST: [2]Datos!$C$2:$C$7

Sheet Entregable
A1: COTIZACIÓN PLANTA METALES SIGRAMA:
A3: PROYECTO: | B3: COTIZAZION SIGRAMA 20837 - 20961 | H3: No. Cot: | I3: 005
A4: FECHA REQ.: | B4: 46077 | H4: Fecha Cot.: | I4: 46077
A5: ATENCIÓN: | B5: ING. JOSUE MESTA | H5: Piezas: | I5: =SUM(G11:G22) -> 720
A6: ELABORADO POR: | B6: ING. JESÚS A. MORALES L.
A7: PRESENTAMOS A SU AMABLE CONSIDERACIÓN:
A9: PARTIDA | B9: PARTIDA | F9: UNIDAD | G9: CANT. | H9: P.U. | I9: IMPORTE | L9: 16
A10: 1 | B10: =+'REQ. PINTADO'!B3 -> 12-6010-01 | F10: PZA | G10: =+'REQ. PINTADO'!C3 -> 48 | H10: =+ROUND(Q10,2) -> 86.88 | I10: =+H10*G10 -> 4170.24 | Q10: =+'REQ. PINTADO'!J3 -> 86.877478
A11: 2 | B11: =+'REQ. PINTADO'!B4 -> 11-D-3402-01 | F11: PZA | G11: =+'REQ. PINTADO'!C4 -> 48 | H11: =+ROUND(Q11,2) -> 134.22 | I11: =+H11*G11 -> 6442.56 | Q11: =+'REQ. PINTADO'!J4 -> 134.22
A12: 3 | B12: =+'REQ. PINTADO'!B5 -> 17-D-6043-02 | F12: PZA | G12: =+'REQ. PINTADO'!C5 -> 96 | H12: =+ROUND(Q12,2) -> 122.83 | I12: =+H12*G12 -> 11791.68 | Q12: =+'REQ. PINTADO'!J5 -> 122.83364
A13: 4 | B13: =+'REQ. PINTADO'!B6 -> 17-D-6047-01 | F13: PZA | G13: =+'REQ. PINTADO'!C6 -> 48 | H13: =+ROUND(Q13,2) -> 80.7 | I13: =+H13*G13 -> 3873.6 | Q13: =+'REQ. PINTADO'!J6 -> 80.697706
A14: 5 | B14: =+'REQ. PINTADO'!B7 -> 12-6355-03 | F14: PZA | G14: =+'REQ. PINTADO'!C7 -> 48 | H14: =+ROUND(Q14,2) -> 198.67 | I14: =+H14*G14 -> 9536.16 | Q14: =+'REQ. PINTADO'!J7 -> 198.67165
A15: 6 | B15: =+'REQ. PINTADO'!B8 -> PP21340-01 | F15: PZA | G15: =+'REQ. PINTADO'!C8 -> 48 | H15: =+ROUND(Q15,2) -> 172.35 | I15: =+H15*G15 -> 8272.8 | Q15: =+'REQ. PINTADO'!J8 -> 172.35241
A16: 7 | B16: =+'REQ. PINTADO'!B9 -> PP22121-01 | F16: PZA | G16: =+'REQ. PINTADO'!C9 -> 48 | H16: =+ROUND(Q16,2) -> 233.42 | I16: =+H16*G16 -> 11204.16 | Q16: =+'REQ. PINTADO'!J9 -> 233.41593
A17: 8 | B17: =+'REQ. PINTADO'!B10 -> 11-D-3408-01 | F17: PZA | G17: =+'REQ. PINTADO'!C10 -> 96 | H17: =+ROUND(Q17,2) -> 69.08 | I17: =+H17*G17 -> 6631.68 | Q17: =+'REQ. PINTADO'!J10 -> 69.078616
A18: 9 | B18: =+'REQ. PINTADO'!B11 -> PP21341-12 | F18: PZA | G18: =+'REQ. PINTADO'!C11 -> 48 | H18: =+ROUND(Q18,2) -> 198.9 | I18: =+H18*G18 -> 9547.2 | Q18: =+'REQ. PINTADO'!J11 -> 198.90167
A19: 10 | B19: =+'REQ. PINTADO'!B12 -> 12-6010-09 | F19: PZA | G19: =+'REQ. PINTADO'!C12 -> 48 | H19: =+ROUND(Q19,2) -> 115.32 | I19: =+H19*G19 -> 5535.36 | Q19: =+'REQ. PINTADO'!J12 -> 115.31857
A20: 11 | B20: =+'REQ. PINTADO'!B13 -> PP22124-01 | F20: PZA | G20: =+'REQ. PINTADO'!C13 -> 48 | H20: =+ROUND(Q20,2) -> 253.35 | I20: =+H20*G20 -> 12160.8 | Q20: =+'REQ. PINTADO'!J13 -> 253.34758
A21: 12 | B21: =+'REQ. PINTADO'!B14 -> 11-D-3409-02 | F21: PZA | G21: =+'REQ. PINTADO'!C14 -> 144 | H21: =+ROUND(Q21,2) -> 129.08 | I21: =+H21*G21 -> 18587.52 | Q21: =+'REQ. PINTADO'!J14 -> 129.08107
F22: SUB-TOTAL | I22: =SUM(I10:I21) -> 107753.76 | K22: =+I22*16 -> 1724060.2
H23: I.V.A. | I23: =+I22*0.16 -> 17240.602
F24: TOTAL | I24: =+I23+I22 -> 124994.36
C26: Entrega | D26: 1 | E26: 2 | F26: 3
C27: Real | D27: =+TODAY()+10 -> 46087 | E27: =+D27+10 -> 46097 | F27: =+F28 -> 46113
C28: Requerido | D28: 46076 | E28: 46094 | F28: 46113
C29: Piezas | D29: 288 | E29: 272 | F29: 208
B31: TIEMPO DE ENTREGA: | D31: AJUSTES AL PROGRAMA…!!!
B32: PRIMER PARCIALIDAD: | D32: =+D27 -> 46087
B33: ENTREGA FINAL: | D33: =+F27 -> 46113
B34: jesus.morales@sigrama.com.mx
B35: cel: 871.7954493
B36: DIR. PLANTA METALES

Sheet Analisis
B2: ANALISIS DE COSTO PROYECTO | I2: Criterios
D3: galvanizado | F3: pintuta
B4: 1 | C4: MATERIAL | D4: =+'REQ GALV'!C136 -> 2081961.4 | E4: =+D4/D8 -> 0.40954748 | F4: =+'REQ. PINTADO'!K15 -> 26248.904 | G4: =+F4/F8 -> 0.30450093 | I4: Desperdicio | J4: 0.33
B5: 2 | C5: CORTE LASER | D5: =+'REQ GALV'!D136 -> 1794654 | E5: =+D5/D8 -> 0.35303057 | F5: =+'REQ. PINTADO'!L15 -> 8930.131 | G5: =+F5/F8 -> 0.10359416 | I5: Tarifa | J5: T5.0
B6: 3 | C6: DOBLEZ | D6: =+'REQ GALV'!E136 -> 1206950 | E6: =+D6/D8 -> 0.23742195 | F6: =+'REQ. PINTADO'!M15 -> 45600 | G6: =+F6/F8 -> 0.5289837 | I6: Doblez Precio x Golpe | J6: 25
B7: 4 | C7: PINTURA | D7: 0 | E7: =+D7/D8 -> 0 | F7: =+'REQ. PINTADO'!N15 -> 5424 | G7: =+F7/F8 -> 0.062921219 | I7: Punzon Precio x Golpe | J7: 25
C8: $ Costo | D8: =SUM(D4:D7) -> 5083565.4 | E8: 1 | F8: =SUM(F4:F7) -> 86203.035 | G8: 1 | I8: Pintura | J8: 106.54762
C9: Margen de Utilidad | D9: =+D10-D8 -> 1270891.3 | E9: 0.2 | F9: =+F10-F8 -> 21550.759 | G9: =+E9 -> 0.2
C10: Precio Venta | D10: =+D8/(1-E9) -> 6354456.7 | F10: =+F8/(1-G9) -> 107753.79

Sheet REQ GALV
A1: PARTE | B1: CANTIDAD | C1: COSTO | F1: COSTO TOTAL | G1: P.V. | H1: TOTAL
C2: MAT | D2: LASER | E2: DOBLEZ
A3: 11-6284-01 | B3: 210 | C3: =+VLOOKUP(A3,'COT. GAL'!B:AC,11,FALSE) -> 17.858649 | D3: =+VLOOKUP(A3,'COT. GAL'!B:AC,20,FALSE)+VLOOKUP(A3,'COT. GAL'!B:AC,24,FALSE) -> 32.622044 | E3: =+VLOOKUP(A3,'COT. GAL'!B:AE,27,FALSE)+VLOOKUP(A3,'COT. GAL'!B:AE,30,FALSE) -> 100 | F3: =+C3+D3+E3 -> 150.48069 | G3: =+F3/(1-Analisis!$E$9) -> 188.10087 | H3: =+G3*B3 -> 39501.182
A4: 11-6285-01 | B4: 1217 | C4: =+VLOOKUP(A4,'COT. GAL'!B:AC,11,FALSE) -> 15.169093 | D4: =+VLOOKUP(A4,'COT. GAL'!B:AC,20,FALSE)+VLOOKUP(A4,'COT. GAL'!B:AC,24,FALSE) -> 34.885165 | E4: =+VLOOKUP(A4,'COT. GAL'!B:AE,27,FALSE)+VLOOKUP(A4,'COT. GAL'!B:AE,30,FALSE) -> 100 | F4: =+C4+D4+E4 -> 150.05426 | G4: =+F4/(1-Analisis!$E$9) -> 187.56782 | H4: =+G4*B4 -> 228270.04
A5: 11-6355-01 | B5: 180 | C5: =+VLOOKUP(A5,'COT. GAL'!B:AC,11,FALSE) -> 12.3424 | D5: =+VLOOKUP(A5,'COT. GAL'!B:AC,20,FALSE)+VLOOKUP(A5,'COT. GAL'!B:AC,24,FALSE) -> 33.668639 | E5: =+VLOOKUP(A5,'COT. GAL'!B:AE,27,FALSE)+VLOOKUP(A5,'COT. GAL'!B:AE,30,FALSE) -> 100 | F5: =+C5+D5+E5 -> 146.01104 | G5: =+F5/(1-Analisis!$E$9) -> 182.5138 | H5: =+G5*B5 -> 32852.484
A6: 11-6474-01 | B6: 120 | C6: =+VLOOKUP(A6,'COT. GAL'!B:AC,11,FALSE) -> 29.250358 | D6: =+VLOOKUP(A6,'COT. GAL'!B:AC,20,FALSE)+VLOOKUP(A6,'COT. GAL'!B:AC,24,FALSE) -> 41.593287 | E6: =+VLOOKUP(A6,'COT. GAL'!B:AE,27,FALSE)+VLOOKUP(A6,'COT. GAL'!B:AE,30,FALSE) -> 100 | F6: =+C6+D6+E6 -> 170.84364 | G6: =+F6/(1-Analisis!$E$9) -> 213.55456 | H6: =+G6*B6 -> 25626.547
A7: 11-A-6030-05 | B7: 30 | C7: =+VLOOKUP(A7,'COT. GAL'!B:AC,11,FALSE) -> 5.0983333 | D7: =+VLOOKUP(A7,'COT. GAL'!B:AC,20,FALSE)+VLOOKUP(A7,'COT. GAL'!B:AC,24,FALSE) -> 20.106499 | E7: =+VLOOKUP(A7,'COT. GAL'!B:AE,27,FALSE)+VLOOKUP(A7,'COT. GAL'!B:AE,30,FALSE) -> 0 | F7: =+C7+D7+E7 -> 25.204832 | G7: =+F7/(1-Analisis!$E$9) -> 31.50604 | H7: =+G7*B7 -> 945.1812
A8: 11-A-6068-01 | B8: 150 | C8: =+VLOOKUP(A8,'COT. GAL'!B:AC,11,FALSE) -> 5.1932344 | D8: =+VLOOKUP(A8,'COT. GAL'!B:AC,20,FALSE)+VLOOKUP(A8,'COT. GAL'!B:AC,24,FALSE) -> 18.346364 | E8: =+VLOOKUP(A8,'COT. GAL'!B:AE,27,FALSE)+VLOOKUP(A8,'COT. GAL'!B:AE,30,FALSE) -> 0 | F8: =+C8+D8+E8 -> 23.539598 | G8: =+F8/(1-Analisis!$E$9) -> 29.424498 | H8: =+G8*B8 -> 4413.6747
A9: 11-A-6160-01 | B9: 120 | C9: =+VLOOKUP(A9,'COT. GAL'!B:AC,11,FALSE) -> 4.0454167 | D9: =+VLOOKUP(A9,'COT. GAL'!B:AC,20,FALSE)+VLOOKUP(A9,'COT. GAL'!B:AC,24,FALSE) -> 34.048484 | E9: =+VLOOKUP(A9,'COT. GAL'!B:AE,27,FALSE)+VLOOKUP(A9,'COT. GAL'!B:AE,30,FALSE) -> 25 | F9: =+C9+D9+E9 -> 63.093901 | G9: =+F9/(1-Analisis!$E$9) -> 78.867376 | H9: =+G9*B9 -> 9464.0851
A10: 11-A-6201-01 | B10: 4800 | C10: =+VLOOKUP(A10,'COT. GAL'!B:AC,11,FALSE) -> 24.460667 | D10: =+VLOOKUP(A10,'COT. GAL'!B:AC,20,FALSE)+VLOOKUP(A10,'COT. GAL'!B:AC,24,FALSE) -> 47.417937 | E10: =+VLOOKUP(A10,'COT. GAL'!B:AE,27,FALSE)+VLOOKUP(A10,'COT. GAL'!B:AE,30,FALSE) -> 0 | F10: =+C10+D10+E10 -> 71.878604 | G10: =+F10/(1-Analisis!$E$9) -> 89.848256 | H10: =+G10*B10 -> 431271.63
A11: 11-A-6271-01 | B11: 510 | C11: =+VLOOKUP(A11,'COT. GAL'!B:AC,11,FALSE) -> 15.79375 | D11: =+VLOOKUP(A11,'COT. GAL'!B:AC,20,FALSE)+VLOOKUP(A11,'COT. GAL'!B:AC,24,FALSE) -> 27.984357 | E11: =+VLOOKUP(A11,'COT. GAL'!B:AE,27,FALSE)+VLOOKUP(A11,'COT. GAL'!B:AE,30,FALSE) -> 0 | F11: =+C11+D11+E11 -> 43.778107 | G11: =+F11/(1-Analisis!$E$9) -> 54.722633 | H11: =+G11*B11 -> 27908.543
A12: 11-A-6340-01 | B12: 2400 | C12: =+VLOOKUP(A12,'COT. GAL'!B:AC,11,FALSE) -> 32.022521 | D12: =+VLOOKUP(A12,'COT. GAL'!B:AC,20,FALSE)+VLOOKUP(A12,'COT. GAL'!B:AC,24,FALSE) -> 48.459003 | E12: =+VLOOKUP(A12,'COT. GAL'!B:AE,27,FALSE)+VLOOKUP(A12,'COT. GAL'!B:AE,30,FALSE) -> 0 | F12: =+C12+D12+E12 -> 80.481524 | G12: =+F12/(1-Analisis!$E$9) -> 100.6019 | H12: =+G12*B12 -> 241444.57
A13: 11-D-6195-03 | B13: 450 | C13: =+VLOOKUP(A13,'COT. GAL'!B:AC,11,FALSE) -> 7.2928333 | D13: =+VLOOKUP(A13,'COT. GAL'!B:AC,20,FALSE)+VLOOKUP(A13,'COT. GAL'!B:AC,24,FALSE) -> 30.113917 | E13: =+VLOOKUP(A13,'COT. GAL'!B:AE,27,FALSE)+VLOOKUP(A13,'COT. GAL'!B:AE,30,FALSE) -> 0 | F13: =+C13+D13+E13 -> 37.40675 | G13: =+F13/(1-Analisis!$E$9) -> 46.758437 | H13: =+G13*B13 -> 21041.297
A14: 11-D-6218-01 | B14: 45 | C14: =+VLOOKUP(A14,'COT. GAL'!B:AC,11,FALSE) -> 68.83282 | D14: =+VLOOKUP(A14,'COT. GAL'!B:AC,20,FALSE)+VLOOKUP(A14,'COT. GAL'!B:AC,24,FALSE) -> 56.858352 | E14: =+VLOOKUP(A14,'COT. GAL'!B:AE,27,FALSE)+VLOOKUP(A14,'COT. GAL'!B:AE,30,FALSE) -> 25 | F14: =+C14+D14+E14 -> 150.69117 | G14: =+F14/(1-Analisis!$E$9) -> 188.36397 | H14: =+G14*B14 -> 8476.3784
... A135: PP7722-13 | B135: 30 | C135: =+VLOOKUP(A135,'COT. GAL'!B:AC,11,FALSE) -> 129.5323 | D135: =+VLOOKUP(A135,'COT. GAL'!B:AC,20,FALSE)+VLOOKUP(A135,'COT. GAL'!B:AC,24,FALSE) -> 91.475225 | E135: =+VLOOKUP(A135,'COT. GAL'!B:AE,27,FALSE)+VLOOKUP(A135,'COT. GAL'!B:AE,30,FALSE) -> 100 | F135: =+C135+D135+E135 -> 321.00752 | G135: =+F135/(1-Analisis!$E$9) -> 401.2594 | H135: =+G135*B135 -> 12037.782
C136: =+SUMPRODUCT(C3:C135,B3:B135) -> 2081961.4 | D136: =+SUMPRODUCT(D3:D135,B3:B135) -> 1794654 | E136: =+SUMPRODUCT(E3:E135,B3:B135) -> 1206950 | F136: =SUM(C136:E136) -> 5083565.4 | H136: =SUM(H3:H135) -> 6354456.7

Sheet COT. GAL
A1: No. | B1: Numero Parte | C1: Cantidad | D1: P.F. | E1: Material | F1: Acabado | G1: Ancho (in) | H1: Longitud (in) | I1: Espesor (in) | J1: Peso (lb) | K1: $ / Kg | L1: $ Material | M1: TARIFA | N1: $/Hr | O1: Material | P1: Cal. Corte | Q1: Velocidad | R1: Tarifa $/mm | S1: Tiempo corte laser | T1: Long corte (mm) | U1: $ Corte | V1: Objetos | W1: Tiempo por Objeto | X1: Total Tiempo x Objeto | Y1: $ Objetos | Z1: Golpes | AA1: Tiempo (min) | AB1: $ Golpes | AC1: Punzonado | AD1: Tiempo (min) | AE1: $ Punz. | AF1: COSTO | AG1: P.V. | AH1: TOTAL | AI1: MATERIAL
A2: 1 | B2: P12365-272 | C2: =IFERROR(VLOOKUP(B2,'REQ GALV'!A:B,2,0),0) -> 0 | D2: =+AG2 -> 1205.3542 | E2: 12GA | F2: DECAPADO | G2: 23.325 | H2: 41.02 | I2: 0.105 | J2: 28.408 | K2: =+L2*2.2/J2 -> 54.749287 | L2: =+VLOOKUP(E2,Material!$H$2:$M$17,6,FALSE)*G2*H2*(1+Material!$K$14) -> 706.96261 | M2: =+Analisis!$J$5 -> T5.0 | N2: =+VLOOKUP(M2,Material!$A$3:$B$58,2,FALSE) -> 5000 | O2: ACERO A36 | P2: Cal 12 | Q2: =+IF(O2="ACERO A36",VLOOKUP(P2,'Velocidades Std 1500 w'!$B$2:$F$15,5,FALSE),IF(O2="INOXIDABLE",VLOOKUP(P2,'Velocidades Std 1500 w'!$B$17:$F$28,5,FALSE),IF(O2="ALUMINIO",VLOOKUP(P2,'Velocidades Std 1500 w'!$B$30:$F$38,5,FALSE)))) -> 4.3859649e-06 | R2: =+Q2*N2 -> 0.021929825 | S2: =+Q2*T2*3600 -> 62.150926 | T2: =(+H2*2+G2*2+V2*1.05)*25.4*1.05 -> 3936.2253 | U2: =+T2*R2 -> 86.32073 | V2: 18 | W2: =+IF(O2="ACERO A36",VLOOKUP(P2,'Tiempo Objeto'!$B$2:$C$12,2,FALSE),IF(O2="INOXIDABLE",VLOOKUP(P2,'Tiempo Objeto'!$B$14:$C$22,2,FALSE),IF(O2="ALUMINIO",VLOOKUP(P2,'Tiempo Objeto'!$B$24:$C$32,2,FALSE)))) -> 1.84 | X2: =+W2*V2 -> 33.12 | Y2: =+X2*N2/3600 -> 46 | Z2: 5 | AA2: =30*Z2+Z2*$C2*1.5 -> 150 | AB2: =+Z2*Analisis!$J$6 -> 125 | AC2: 0 | AD2: =30*AC2+AC2*$C2*1.5 -> 0 | AE2: =+AD2*Analisis!$J$7 -> 0 | AF2: =+L2+U2+Y2+AB2+AE2 -> 964.28334 | AG2: =+AF2/(1-Analisis!$E$9) -> 1205.3542 | AH2: =+AG2*C2 -> 0
A3: 2 | B3: P12365-311 | C3: =IFERROR(VLOOKUP(B3,'REQ GALV'!A:B,2,0),0) -> 0 | D3: =+AG3 -> 2182.523 | E3: 12GA | F3: DECAPADO | G3: 19.04 | H3: 39.39 | I3: 0.105 | J3: 28.24 | K3: =+L3*2.2/J3 -> 43.170795 | L3: =+VLOOKUP(E3,Material!$H$2:$M$17,6,FALSE)*G3*H3*(1+Material!$K$14) -> 554.15603 | M3: =+Analisis!$J$5 -> T5.0 | N3: =+VLOOKUP(M3,Material!$A$3:$B$58,2,FALSE) -> 5000 | O3: ACERO A36 | P3: Cal 12 | Q3: =+IF(O3="ACERO A36",VLOOKUP(P3,'Velocidades Std 1500 w'!$B$2:$F$15,5,FALSE),IF(O3="INOXIDABLE",VLOOKUP(P3,'Velocidades Std 1500 w'!$B$17:$F$28,5,FALSE),IF(O3="ALUMINIO",VLOOKUP(P3,'Velocidades Std 1500 w'!$B$30:$F$38,5,FALSE)))) -> 4.3859649e-06 | R3: =+Q3*N3 -> 0.021929825 | S3: =+Q3*T3*3600 -> 251.34089 | T3: =(+H3*2+G3*2+V3*1.5)*25.4*1.05 -> 15918.256 | U3: =+T3*R3 -> 349.08457 | V3: 320 | W3: =+IF(O3="ACERO A36",VLOOKUP(P3,'Tiempo Objeto'!$B$2:$C$12,2,FALSE),IF(O3="INOXIDABLE",VLOOKUP(P3,'Tiempo Objeto'!$B$14:$C$22,2,FALSE),IF(O3="ALUMINIO",VLOOKUP(P3,'Tiempo Objeto'!$B$24:$C$32,2,FALSE)))) -> 1.84 | X3: =+W3*V3 -> 588.8 | Y3: =+X3*N3/3600 -> 817.77778 | Z3: 1 | AA3: =30*Z3+Z3*$C3*1.5 -> 30 | AB3: =+Z3*Analisis!$J$6 -> 25 | AC3: 0 | AD3: =30*AC3+AC3*$C3*1.5 -> 0 | AE3: =+AD3*Analisis!$J$7 -> 0 | AF3: =+L3+U3+Y3+AB3+AE3 -> 1746.0184 | AG3: =+AF3/(1-Analisis!$E$9) -> 2182.523 | AH3: =+AG3*C3 -> 0
A4: 2 | B4: 11-D-9570-01 | C4: =IFERROR(VLOOKUP(B4,'REQ GALV'!A:B,2,0),0) -> 0 | D4: =+AG4 -> 220.64871 | E4: 12GA | F4: DECAPADO | G4: 5 | H4: 11 | I4: 0.105 | J4: 28.24 | K4: =+L4*2.2/J4 -> 3.1659191 | L4: =+VLOOKUP(E4,Material!$H$2:$M$17,6,FALSE)*G4*H4*(1+Material!$K$14) -> 40.638889 | M4: =+Analisis!$J$5 -> T5.0 | N4: =+VLOOKUP(M4,Material!$A$3:$B$58,2,FALSE) -> 5000 | O4: ACERO A36 | P4: Cal 12 | Q4: =+IF(O4="ACERO A36",VLOOKUP(P4,'Velocidades Std 1500 w'!$B$2:$F$15,5,FALSE),IF(O4="INOXIDABLE",VLOOKUP(P4,'Velocidades Std 1500 w'!$B$17:$F$28,5,FALSE),IF(O4="ALUMINIO",VLOOKUP(P4,'Velocidades Std 1500 w'!$B$30:$F$38,5,FALSE)))) -> 4.3859649e-06 | R4: =+Q4*N4 -> 0.021929825 | S4: =+Q4*T4*3600 -> 16.633658 | T4: =(+H4*2+G4*2+V4*1.5)*25.4*1.05 -> 1053.465 | U4: =+T4*R4 -> 23.102303 | V4: 5 | W4: =+IF(O4="ACERO A36",VLOOKUP(P4,'Tiempo Objeto'!$B$2:$C$12,2,FALSE),IF(O4="INOXIDABLE",VLOOKUP(P4,'Tiempo Objeto'!$B$14:$C$22,2,FALSE),IF(O4="ALUMINIO",VLOOKUP(P4,'Tiempo Objeto'!$B$24:$C$32,2,FALSE)))) -> 1.84 | X4: =+W4*V4 -> 9.2 | Y4: =+X4*N4/3600 -> 12.777778 | Z4: 4 | AA4: =30*Z4+Z4*$C4*1.5 -> 120 | AB4: =+Z4*Analisis!$J$6 -> 100 | AC4: 0 | AD4: =30*AC4+AC4*$C4*1.5 -> 0 | AE4: =+AD4*Analisis!$J$7 -> 0 | AF4: =+L4+U4+Y4+AB4+AE4 -> 176.51897 | AG4: =+AF4/(1-Analisis!$E$9) -> 220.64871 | AH4: =+AG4*C4 -> 0
A5: 2 | B5: PP14252-17-MO | C5: =IFERROR(VLOOKUP(B5,'REQ GALV'!A:B,2,0),0) -> 0 | D5: =+AG5 -> 556.43267 | E5: 188al | F5: DECAPADO | G5: 5.048 | H5: 40 | I5: 0.105 | J5: 28.24 | K5: =+L5*2.2/J5 -> 17.434429 | L5: =+VLOOKUP(E5,Material!$H$2:$M$17,6,FALSE)*G5*H5*(1+Material!$K$14) -> 223.79467 | M5: =+Analisis!$J$5 -> T5.0 | N5: =+VLOOKUP(M5,Material!$A$3:$B$58,2,FALSE) -> 5000 | O5: ACERO A36 | P5: Cal 12 | Q5: =+IF(O5="ACERO A36",VLOOKUP(P5,'Velocidades Std 1500 w'!$B$2:$F$15,5,FALSE),IF(O5="INOXIDABLE",VLOOKUP(P5,'Velocidades Std 1500 w'!$B$17:$F$28,5,FALSE),IF(O5="ALUMINIO",VLOOKUP(P5,'Velocidades Std 1500 w'!$B$30:$F$38,5,FALSE)))) -> 4.3859649e-06 | R5: =+Q5*N5 -> 0.021929825 | S5: =+Q5*T5*3600 -> 50.573058 | T5: =(+H5*2+G5*2+V5*1.5)*25.4*1.05 -> 3202.9603 | U5: =+T5*R5 -> 70.240358 | V5: 20 | W5: =+IF(O5="ACERO A36",VLOOKUP(P5,'Tiempo Objeto'!$B$2:$C$12,2,FALSE),IF(O5="INOXIDABLE",VLOOKUP(P5,'Tiempo Objeto'!$B$14:$C$22,2,FALSE),IF(O5="ALUMINIO",VLOOKUP(P5,'Tiempo Objeto'!$B$24:$C$32,2,FALSE)))) -> 1.84 | X5: =+W5*V5 -> 36.8 | Y5: =+X5*N5/3600 -> 51.111111 | Z5: 4 | AA5: =30*Z5+Z5*$C5*1.5 -> 120 | AB5: =+Z5*Analisis!$J$6 -> 100 | AC5: 0 | AD5: =30*AC5+AC5*$C5*1.5 -> 0 | AE5: =+AD5*Analisis!$J$7 -> 0 | AF5: =+L5+U5+Y5+AB5+AE5 -> 445.14614 | AG5: =+AF5/(1-Analisis!$E$9) -> 556.43267 | AH5: =+AG5*C5 -> 0
A6: 1 | B6: 11-B-9087-01 | C6: =IFERROR(VLOOKUP(B6,'REQ GALV'!A:B,2,0),0) -> 0 | D6: =+AG6 -> 284.81814 | E6: 12GA | F6: DECAPADO | G6: 6.91 | H6: 22.13 | I6: 0.105 | J6: 28.24 | K6: =+L6*2.2/J6 -> 8.8023085 | L6: =+VLOOKUP(E6,Material!$H$2:$M$17,6,FALSE)*G6*H6*(1+Material!$K$14) -> 112.98963 | M6: =+Analisis!$J$5 -> T5.0 | N6: =+VLOOKUP(M6,Material!$A$3:$B$58,2,FALSE) -> 5000 | O6: ACERO A36 | P6: Cal 12 | Q6: =+IF(O6="ACERO A36",VLOOKUP(P6,'Velocidades Std 1500 w'!$B$2:$F$15,5,FALSE),IF(O6="INOXIDABLE",VLOOKUP(P6,'Velocidades Std 1500 w'!$B$17:$F$28,5,FALSE),IF(O6="ALUMINIO",VLOOKUP(P6,'Velocidades Std 1500 w'!$B$30:$F$38,5,FALSE)))) -> 4.3859649e-06 | R6: =+Q6*N6 -> 0.021929825 | S6: =+Q6*T6*3600 -> 30.142715 | T6: =(+H6*2+G6*2+V6*1.5)*25.4*1.05 -> 1909.0386 | U6: =+T6*R6 -> 41.864882 | V6: 9 | W6: =+IF(O6="ACERO A36",VLOOKUP(P6,'Tiempo Objeto'!$B$2:$C$12,2,FALSE),IF(O6="INOXIDABLE",VLOOKUP(P6,'Tiempo Objeto'!$B$14:$C$22,2,FALSE),IF(O6="ALUMINIO",VLOOKUP(P6,'Tiempo Objeto'!$B$24:$C$32,2,FALSE)))) -> 1.84 | X6: =+W6*V6 -> 16.56 | Y6: =+X6*N6/3600 -> 23 | Z6: 2 | AA6: =30*Z6+Z6*$C6*1.5 -> 60 | AB6: =+Z6*Analisis!$J$6 -> 50 | AC6: 0 | AD6: =30*AC6+AC6*$C6*1.5 -> 0 | AE6: =+AD6*Analisis!$J$7 -> 0 | AF6: =+L6+U6+Y6+AB6+AE6 -> 227.85451 | AG6: =+AF6/(1-Analisis!$E$9) -> 284.81814 | AH6: =+AG6*C6 -> 0
A7: 2 | B7: 11-D-9401-01 | C7: =IFERROR(VLOOKUP(B7,'REQ GALV'!A:B,2,0),0) -> 0 | D7: =+AG7 -> 990.2411 | E7: 12GA | F7: DECAPADO | G7: 41.94 | H7: 13.03 | I7: 0.105 | J7: 28.24 | K7: =+L7*2.2/J7 -> 31.456469 | L7: =+VLOOKUP(E7,Material!$H$2:$M$17,6,FALSE)*G7*H7*(1+Material!$K$14) -> 403.78667 | M7: =+Analisis!$J$5 -> T5.0 | N7: =+VLOOKUP(M7,Material!$A$3:$B$58,2,FALSE) -> 5000 | O7: ACERO A36 | P7: Cal 12 | Q7: =+IF(O7="ACERO A36",VLOOKUP(P7,'Velocidades Std 1500 w'!$B$2:$F$15,5,FALSE),IF(O7="INOXIDABLE",VLOOKUP(P7,'Velocidades Std 1500 w'!$B$17:$F$28,5,FALSE),IF(O7="ALUMINIO",VLOOKUP(P7,'Velocidades Std 1500 w'!$B$30:$F$38,5,FALSE)))) -> 4.3859649e-06 | R7: =+Q7*N7 -> 0.021929825 | S7: =+Q7*T7*3600 -> 82.932471 | T7: =(+H7*2+G7*2+V7*1.5)*25.4*1.05 -> 5252.3898 | U7: =+T7*R7 -> 115.18399 | V7: 58 | W7: =+IF(O7="ACERO A36",VLOOKUP(P7,'Tiempo Objeto'!$B$2:$C$12,2,FALSE),IF(O7="INOXIDABLE",VLOOKUP(P7,'Tiempo Objeto'!$B$14:$C$22,2,FALSE),IF(O7="ALUMINIO",VLOOKUP(P7,'Tiempo Objeto'!$B$24:$C$32,2,FALSE)))) -> 1.84 | X7: =+W7*V7 -> 106.72 | Y7: =+X7*N7/3600 -> 148.22222 | Z7: 5 | AA7: =30*Z7+Z7*$C7*1.5 -> 150 | AB7: =+Z7*Analisis!$J$6 -> 125 | AC7: 0 | AD7: =30*AC7+AC7*$C7*1.5 -> 0 | AE7: =+AD7*Analisis!$J$7 -> 0 | AF7: =+L7+U7+Y7+AB7+AE7 -> 792.19288 | AG7: =+AF7/(1-Analisis!$E$9) -> 990.2411 | AH7: =+AG7*C7 -> 0
A8: 2 | B8: 11-D-9401-02 | C8: =IFERROR(VLOOKUP(B8,'REQ GALV'!A:B,2,0),0) -> 0 | D8: =+AG8 -> 936.2538 | E8: 12GA | F8: DECAPADO | G8: 37.94 | H8: 13.03 | I8: 0.105 | J8: 28.24 | K8: =+L8*2.2/J8 -> 28.456329 | L8: =+VLOOKUP(E8,Material!$H$2:$M$17,6,FALSE)*G8*H8*(1+Material!$K$14) -> 365.27578 | M8: =+Analisis!$J$5 -> T5.0 | N8: =+VLOOKUP(M8,Material!$A$3:$B$58,2,FALSE) -> 5000 | O8: ACERO A36 | P8: Cal 12 | Q8: =+IF(O8="ACERO A36",VLOOKUP(P8,'Velocidades Std 1500 w'!$B$2:$F$15,5,FALSE),IF(O8="INOXIDABLE",VLOOKUP(P8,'Velocidades Std 1500 w'!$B$17:$F$28,5,FALSE),IF(O8="ALUMINIO",VLOOKUP(P8,'Velocidades Std 1500 w'!$B$30:$F$38,5,FALSE)))) -> 4.3859649e-06 | R8: =+Q8*N8 -> 0.021929825 | S8: =+Q8*T8*3600 -> 79.563628 | T8: =(+H8*2+G8*2+V8*1.5)*25.4*1.05 -> 5039.0298 | U8: =+T8*R8 -> 110.50504 | V8: 58 | W8: =+IF(O8="ACERO A36",VLOOKUP(P8,'Tiempo Objeto'!$B$2:$C$12,2,FALSE),IF(O8="INOXIDABLE",VLOOKUP(P8,'Tiempo Objeto'!$B$14:$C$22,2,FALSE),IF(O8="ALUMINIO",VLOOKUP(P8,'Tiempo Objeto'!$B$24:$C$32,2,FALSE)))) -> 1.84 | X8: =+W8*V8 -> 106.72 | Y8: =+X8*N8/3600 -> 148.22222 | Z8: 5 | AA8: =30*Z8+Z8*$C8*1.5 -> 150 | AB8: =+Z8*Analisis!$J$6 -> 125 | AC8: 0 | AD8: =30*AC8+AC8*$C8*1.5 -> 0 | AE8: =+AD8*Analisis!$J$7 -> 0 | AF8: =+L8+U8+Y8+AB8+AE8 -> 749.00304 | AG8: =+AF8/(1-Analisis!$E$9) -> 936.2538 | AH8: =+AG8*C8 -> 0
A9: 2 | B9: 11-D-9401-03 | C9: =IFERROR(VLOOKUP(B9,'REQ GALV'!A:B,2,0),0) -> 0 | D9: =+AG9 -> 963.24745 | E9: 12GA | F9: DECAPADO | G9: 39.94 | H9: 13.03 | I9: 0.105 | J9: 28.24 | K9: =+L9*2.2/J9 -> 29.956399 | L9: =+VLOOKUP(E9,Material!$H$2:$M$17,6,FALSE)*G9*H9*(1+Material!$K$14) -> 384.53123 | M9: =+Analisis!$J$5 -> T5.0 | N9: =+VLOOKUP(M9,Material!$A$3:$B$58,2,FALSE) -> 5000 | O9: ACERO A36 | P9: Cal 12 | Q9: =+IF(O9="ACERO A36",VLOOKUP(P9,'Velocidades Std 1500 w'!$B$2:$F$15,5,FALSE),IF(O9="INOXIDABLE",VLOOKUP(P9,'Velocidades Std 1500 w'!$B$17:$F$28,5,FALSE),IF(O9="ALUMINIO",VLOOKUP(P9,'Velocidades Std 1500 w'!$B$30:$F$38,5,FALSE)))) -> 4.3859649e-06 | R9: =+Q9*N9 -> 0.021929825 | S9: =+Q9*T9*3600 -> 81.248049 | T9: =(+H9*2+G9*2+V9*1.5)*25.4*1.05 -> 5145.7098 | U9: =+T9*R9 -> 112.84451 | V9: 58 | W9: =+IF(O9="ACERO A36",VLOOKUP(P9,'Tiempo Objeto'!$B$2:$C$12,2,FALSE),IF(O9="INOXIDABLE",VLOOKUP(P9,'Tiempo Objeto'!$B$14:$C$22,2,FALSE),IF(O9="ALUMINIO",VLOOKUP(P9,'Tiempo Objeto'!$B$24:$C$32,2,FALSE)))) -> 1.84 | X9: =+W9*V9 -> 106.72 | Y9: =+X9*N9/3600 -> 148.22222 | Z9: 5 | AA9: =30*Z9+Z9*$C9*1.5 -> 150 | AB9: =+Z9*Analisis!$J$6 -> 125 | AC9: 0 | AD9: =30*AC9+AC9*$C9*1.5 -> 0 | AE9: =+AD9*Analisis!$J$7 -> 0 | AF9: =+L9+U9+Y9+AB9+AE9 -> 770.59796 | AG9: =+AF9/(1-Analisis!$E$9) -> 963.24745 | AH9: =+AG9*C9 -> 0
A10: 2 | B10: 11-D-9401-04 | C10: =IFERROR(VLOOKUP(B10,'REQ GALV'!A:B,2,0),0) -> 0 | D10: =+AG10 -> 1044.2284 | E10: 12GA | F10: DECAPADO | G10: 45.94 | H10: 13.03 | I10: 0.105 | J10: 28.24 | K10: =+L10*2.2/J10 -> 34.456609 | L10: =+VLOOKUP(E10,Material!$H$2:$M$17,6,FALSE)*G10*H10*(1+Material!$K$14) -> 442.29756 | M10: =+Analisis!$J$5 -> T5.0 | N10: =+VLOOKUP(M10,Material!$A$3:$B$58,2,FALSE) -> 5000 | O10: ACERO A36 | P10: Cal 12 | Q10: =+IF(O10="ACERO A36",VLOOKUP(P10,'Velocidades Std 1500 w'!$B$2:$F$15,5,FALSE),IF(O10="INOXIDABLE",VLOOKUP(P10,'Velocidades Std 1500 w'!$B$17:$F$28,5,FALSE),IF(O10="ALUMINIO",VLOOKUP(P10,'Velocidades Std 1500 w'!$B$30:$F$38,5,FALSE)))) -> 4.3859649e-06 | R10: =+Q10*N10 -> 0.021929825 | S10: =+Q10*T10*3600 -> 86.301313 | T10: =(+H10*2+G10*2+V10*1.5)*25.4*1.05 -> 5465.7498 | U10: =+T10*R10 -> 119.86293 | V10: 58 | W10: =+IF(O10="ACERO A36",VLOOKUP(P10,'Tiempo Objeto'!$B$2:$C$12,2,FALSE),IF(O10="INOXIDABLE",VLOOKUP(P10,'Tiempo Objeto'!$B$14:$C$22,2,FALSE),IF(O10="ALUMINIO",VLOOKUP(P10,'Tiempo Objeto'!$B$24:$C$32,2,FALSE)))) -> 1.84 | X10: =+W10*V10 -> 106.72 | Y10: =+X10*N10/3600 -> 148.22222 | Z10: 5 | AA10: =30*Z10+Z10*$C10*1.5 -> 150 | AB10: =+Z10*Analisis!$J$6 -> 125 | AC10: 0 | AD10: =30*AC10+AC10*$C10*1.5 -> 0 | AE10: =+AD10*Analisis!$J$7 -> 0 | AF10: =+L10+U10+Y10+AB10+AE10 -> 835.38272 | AG10: =+AF10/(1-Analisis!$E$9) -> 1044.2284 | AH10: =+AG10*C10 -> 0
A11: 3 | B11: 11-A-9813-01 | C11: =IFERROR(VLOOKUP(B11,'REQ GALV'!A:B,2,0),0) -> 0 | D11: =+AG11 -> 260.30033 | E11: 12GA | F11: DECAPADO | G11: 2.69 | H11: 21.94 | I11: 0.105 | J11: 28.24 | K11: =+L11*2.2/J11 -> 3.3972384 | L11: =+VLOOKUP(E11,Material!$H$2:$M$17,6,FALSE)*G11*H11*(1+Material!$K$14) -> 43.608188 | M11: =+Analisis!$J$5 -> T5.0 | N11: =+VLOOKUP(M11,Material!$A$3:$B$58,2,FALSE) -> 5000 | O11: ACERO A36 | P11: Cal 12 | Q11: =+IF(O11="ACERO A36",VLOOKUP(P11,'Velocidades Std 1500 w'!$B$2:$F$15,5,FALSE),IF(O11="INOXIDABLE",VLOOKUP(P11,'Velocidades Std 1500 w'!$B$17:$F$28,5,FALSE),IF(O11="ALUMINIO",VLOOKUP(P11,'Velocidades Std 1500 w'!$B$30:$F$38,5,FALSE)))) -> 4.3859649e-06 | R11: =+Q11*N11 -> 0.021929825 | S11: =+Q11*T11*3600 -> 36.535093 | T11: =(+H11*2+G11*2+V11*1.5)*25.4*1.05 -> 2313.8892 | U11: =+T11*R11 -> 50.743184 | V11: 25 | W11: =+IF(O11="ACERO A36",VLOOKUP(P11,'Tiempo Objeto'!$B$2:$C$12,2,FALSE),IF(O11="INOXIDABLE",VLOOKUP(P11,'Tiempo Objeto'!$B$14:$C$22,2,FALSE),IF(O11="ALUMINIO",VLOOKUP(P11,'Tiempo Objeto'!$B$24:$C$32,2,FALSE)))) -> 1.84 | X11: =+W11*V11 -> 46 | Y11: =+X11*N11/3600 -> 63.888889 | Z11: 2 | AA11: =30*Z11+Z11*$C11*1.5 -> 60 | AB11: =+Z11*Analisis!$J$6 -> 50 | AC11: 0 | AD11: =30*AC11+AC11*$C11*1.5 -> 0 | AE11: =+AD11*Analisis!$J$7 -> 0 | AF11: =+L11+U11+Y11+AB11+AE11 -> 208.24026 | AG11: =+AF11/(1-Analisis!$E$9) -> 260.30033 | AH11: =+AG11*C11 -> 0
A12: 3 | B12: 11-A-9813-02 | C12: =IFERROR(VLOOKUP(B12,'REQ GALV'!A:B,2,0),0) -> 0 | D12: =+AG12 -> 299.76718 | E12: 12GA | F12: DECAPADO | G12: 2.69 | H12: 31.94 | I12: 0.105 | J12: 28.24 | K12: =+L12*2.2/J12 -> 4.9456607 | L12: =+VLOOKUP(E12,Material!$H$2:$M$17,6,FALSE)*G12*H12*(1+Material!$K$14) -> 63.484299 | M12: =+Analisis!$J$5 -> T5.0 | N12: =+VLOOKUP(M12,Material!$A$3:$B$58,2,FALSE) -> 5000 | O12: ACERO A36 | P12: Cal 12 | Q12: =+IF(O12="ACERO A36",VLOOKUP(P12,'Velocidades Std 1500 w'!$B$2:$F$15,5,FALSE),IF(O12="INOXIDABLE",VLOOKUP(P12,'Velocidades Std 1500 w'!$B$17:$F$28,5,FALSE),IF(O12="ALUMINIO",VLOOKUP(P12,'Velocidades Std 1500 w'!$B$30:$F$38,5,FALSE)))) -> 4.3859649e-06 | R12: =+Q12*N12 -> 0.021929825 | S12: =+Q12*T12*3600 -> 44.957198 | T12: =(+H12*2+G12*2+V12*1.5)*25.4*1.05 -> 2847.2892 | U12: =+T12*R12 -> 62.440553 | V12: 25 | W12: =+IF(O12="ACERO A36",VLOOKUP(P12,'Tiempo Objeto'!$B$2:$C$12,2,FALSE),IF(O12="INOXIDABLE",VLOOKUP(P12,'Tiempo Objeto'!$B$14:$C$22,2,FALSE),IF(O12="ALUMINIO",VLOOKUP(P12,'Tiempo Objeto'!$B$24:$C$32,2,FALSE)))) -> 1.84 | X12: =+W12*V12 -> 46 | Y12: =+X12*N12/3600 -> 63.888889 | Z12: 2 | AA12: =30*Z12+Z12*$C12*1.5 -> 60 | AB12: =+Z12*Analisis!$J$6 -> 50 | AC12: 0 | AD12: =30*AC12+AC12*$C12*1.5 -> 0 | AE12: =+AD12*Analisis!$J$7 -> 0 | AF12: =+L12+U12+Y12+AB12+AE12 -> 239.81374 | AG12: =+AF12/(1-Analisis!$E$9) -> 299.76718 | AH12: =+AG12*C12 -> 0
A13: 3 | B13: 11-A-9813-03 | C13: =IFERROR(VLOOKUP(B13,'REQ GALV'!A:B,2,0),0) -> 0 | D13: =+AG13 -> 339.23402 | E13: 12GA | F13: DECAPADO | G13: 2.69 | H13: 41.94 | I13: 0.105 | J13: 28.24 | K13: =+L13*2.2/J13 -> 6.4940829 | L13: =+VLOOKUP(E13,Material!$H$2:$M$17,6,FALSE)*G13*H13*(1+Material!$K$14) -> 83.36041 | M13: =+Analisis!$J$5 -> T5.0 | N13: =+VLOOKUP(M13,Material!$A$3:$B$58,2,FALSE) -> 5000 | O13: ACERO A36 | P13: Cal 12 | Q13: =+IF(O13="ACERO A36",VLOOKUP(P13,'Velocidades Std 1500 w'!$B$2:$F$15,5,FALSE),IF(O13="INOXIDABLE",VLOOKUP(P13,'Velocidades Std 1500 w'!$B$17:$F$28,5,FALSE),IF(O13="ALUMINIO",VLOOKUP(P13,'Velocidades Std 1500 w'!$B$30:$F$38,5,FALSE)))) -> 4.3859649e-06 | R13: =+Q13*N13 -> 0.021929825 | S13: =+Q13*T13*3600 -> 53.379303 | T13: =(+H13*2+G13*2+V13*1.5)*25.4*1.05 -> 3380.6892 | U13: =+T13*R13 -> 74.137921 | V13: 25 | W13: =+IF(O13="ACERO A36",VLOOKUP(P13,'Tiempo Objeto'!$B$2:$C$12,2,FALSE),IF(O13="INOXIDABLE",VLOOKUP(P13,'Tiempo Objeto'!$B$14:$C$22,2,FALSE),IF(O13="ALUMINIO",VLOOKUP(P13,'Tiempo Objeto'!$B$24:$C$32,2,FALSE)))) -> 1.84 | X13: =+W13*V13 -> 46 | Y13: =+X13*N13/3600 -> 63.888889 | Z13: 2 | AA13: =30*Z13+Z13*$C13*1.5 -> 60 | AB13: =+Z13*Analisis!$J$6 -> 50 | AC13: 0 | AD13: =30*AC13+AC13*$C13*1.5 -> 0 | AE13: =+AD13*Analisis!$J$7 -> 0 | AF13: =+L13+U13+Y13+AB13+AE13 -> 271.38722 | AG13: =+AF13/(1-Analisis!$E$9) -> 339.23402 | AH13: =+AG13*C13 -> 0
A14: 3 | B14: 11-A-9813-04 | C14: =IFERROR(VLOOKUP(B14,'REQ GALV'!A:B,2,0),0) -> 0 | D14: =+AG14 -> 323.44729 | E14: 12GA | F14: DECAPADO | G14: 2.69 | H14: 37.94 | I14: 0.105 | J14: 28.24 | K14: =+L14*2.2/J14 -> 5.874714 | L14: =+VLOOKUP(E14,Material!$H$2:$M$17,6,FALSE)*G14*H14*(1+Material!$K$14) -> 75.409966 | M14: =+Analisis!$J$5 -> T5.0 | N14: =+VLOOKUP(M14,Material!$A$3:$B$58,2,FALSE) -> 5000 | O14: ACERO A36 | P14: Cal 12 | Q14: =+IF(O14="ACERO A36",VLOOKUP(P14,'Velocidades Std 1500 w'!$B$2:$F$15,5,FALSE),IF(O14="INOXIDABLE",VLOOKUP(P14,'Velocidades Std 1500 w'!$B$17:$F$28,5,FALSE),IF(O14="ALUMINIO",VLOOKUP(P14,'Velocidades Std 1500 w'!$B$30:$F$38,5,FALSE)))) -> 4.3859649e-06 | R14: =+Q14*N14 -> 0.021929825 | S14: =+Q14*T14*3600 -> 50.010461 | T14: =(+H14*2+G14*2+V14*1.5)*25.4*1.05 -> 3167.3292 | U14: =+T14*R14 -> 69.458974 | V14: 25 | W14: =+IF(O14="ACERO A36",VLOOKUP(P14,'Tiempo Objeto'!$B$2:$C$12,2,FALSE),IF(O14="INOXIDABLE",VLOOKUP(P14,'Tiempo Objeto'!$B$14:$C$22,2,FALSE),IF(O14="ALUMINIO",VLOOKUP(P14,'Tiempo Objeto'!$B$24:$C$32,2,FALSE)))) -> 1.84 | X14: =+W14*V14 -> 46 | Y14: =+X14*N14/3600 -> 63.888889 | Z14: 2 | AA14: =30*Z14+Z14*$C14*1.5 -> 60 | AB14: =+Z14*Analisis!$J$6 -> 50 | AC14: 0 | AD14: =30*AC14+AC14*$C14*1.5 -> 0 | AE14: =+AD14*Analisis!$J$7 -> 0 | AF14: =+L14+U14+Y14+AB14+AE14 -> 258.75783 | AG14: =+AF14/(1-Analisis!$E$9) -> 323.44729 | AH14: =+AG14*C14 -> 0
... A36: 23 | B36: P11649-242 | C36: =IFERROR(VLOOKUP(B36,'REQ GALV'!A:B,2,0),0) -> 0 | D36: =+AG36 -> 142.11121 | E36: 12GA | F36: DECAPADO | G36: 3.237 | H36: 12 | I36: 0.105 | J36: 28.24 | K36: =+L36*2.2/J36 -> 2.2359448 | L36: =+VLOOKUP(E36,Material!$H$2:$M$17,6,FALSE)*G36*H36*(1+Material!$K$14) -> 28.7014 | M36: =+Analisis!$J$5 -> T5.0 | N36: =+VLOOKUP(M36,Material!$A$3:$B$58,2,FALSE) -> 5000 | O36: ACERO A36 | P36: Cal 12 | Q36: =+IF(O36="ACERO A36",VLOOKUP(P36,'Velocidades Std 1500 w'!$B$2:$F$15,5,FALSE),IF(O36="INOXIDABLE",VLOOKUP(P36,'Velocidades Std 1500 w'!$B$17:$F$28,5,FALSE),IF(O36="ALUMINIO",VLOOKUP(P36,'Velocidades Std 1500 w'!$B$30:$F$38,5,FALSE)))) -> 4.3859649e-06 | R36: =+Q36*N36 -> 0.021929825 | S36: =+Q36*T36*3600 -> 15.991051 | T36: =(+H36*2+G36*2+V36*1.5)*25.4*1.05 -> 1012.7666 | U36: =+T36*R36 -> 22.209793 | V36: 5 | W36: =+IF(O36="ACERO A36",VLOOKUP(P36,'Tiempo Objeto'!$B$2:$C$12,2,FALSE),IF(O36="INOXIDABLE",VLOOKUP(P36,'Tiempo Objeto'!$B$14:$C$22,2,FALSE),IF(O36="ALUMINIO",VLOOKUP(P36,'Tiempo Objeto'!$B$24:$C$32,2,FALSE)))) -> 1.84 | X36: =+W36*V36 -> 9.2 | Y36: =+X36*N36/3600 -> 12.777778 | Z36: 2 | AA36: =30*Z36+Z36*$C36*1.5 -> 60 | AB36: =+Z36*Analisis!$J$6 -> 50 | AC36: 0 | AD36: =30*AC36+AC36*$C36*1.5 -> 0 | AE36: =+AD36*Analisis!$J$7 -> 0 | AF36: =+L36+U36+Y36+AB36+AE36 -> 113.68897 | AG36: =+AF36/(1-Analisis!$E$9) -> 142.11121 | AH36: =+AG36*C36 -> 0
A37: a | B37: PP5309-79 | C37: =IFERROR(VLOOKUP(B37,'REQ GALV'!A:B,2,0),0) -> 0 | D37: =+AG37 -> 94.966953 | E37: 12GA | F37: DECAPADO | G37: 17.5 | H37: 0.946 | I37: 0.105 | J37: 28.24 | K37: =+L37*2.2/J37 -> 0.95294165 | L37: =+VLOOKUP(E37,Material!$H$2:$M$17,6,FALSE)*G37*H37*(1+Material!$K$14) -> 12.232306 | M37: =+Analisis!$J$5 -> T5.0 | N37: =+VLOOKUP(M37,Material!$A$3:$B$58,2,FALSE) -> 5000 | O37: ACERO A36 | P37: Cal 12 | Q37: =+IF(O37="ACERO A36",VLOOKUP(P37,'Velocidades Std 1500 w'!$B$2:$F$15,5,FALSE),IF(O37="INOXIDABLE",VLOOKUP(P37,'Velocidades Std 1500 w'!$B$17:$F$28,5,FALSE),IF(O37="ALUMINIO",VLOOKUP(P37,'Velocidades Std 1500 w'!$B$30:$F$38,5,FALSE)))) -> 4.3859649e-06 | R37: =+Q37*N37 -> 0.021929825 | S37: =+Q37*T37*3600 -> 18.693705 | T37: =(+H37*2+G37*2+V37*1.5)*25.4*1.05 -> 1183.9346 | U37: =+T37*R37 -> 25.963479 | V37: 5 | W37: =+IF(O37="ACERO A36",VLOOKUP(P37,'Tiempo Objeto'!$B$2:$C$12,2,FALSE),IF(O37="INOXIDABLE",VLOOKUP(P37,'Tiempo Objeto'!$B$14:$C$22,2,FALSE),IF(O37="ALUMINIO",VLOOKUP(P37,'Tiempo Objeto'!$B$24:$C$32,2,FALSE)))) -> 1.84 | X37: =+W37*V37 -> 9.2 | Y37: =+X37*N37/3600 -> 12.777778 | Z37: 1 | AA37: =30*Z37+Z37*$C37*1.5 -> 30 | AB37: =+Z37*Analisis!$J$6 -> 25 | AC37: 0 | AD37: =30*AC37+AC37*$C37*1.5 -> 0 | AE37: =+AD37*Analisis!$J$7 -> 0 | AF37: =+L37+U37+Y37+AB37+AE37 -> 75.973562 | AG37: =+AF37/(1-Analisis!$E$9) -> 94.966953 | AH37: =+AG37*C37 -> 0
A38: b | B38: PP7515-161 | C38: =IFERROR(VLOOKUP(B38,'REQ GALV'!A:B,2,0),0) -> 0 | D38: =+AG38 -> 182.92749 | E38: 12GA | F38: DECAPADO | G38: 3.56 | H38: 28.38 | I38: 0.105 | J38: 28.24 | K38: =+L38*2.2/J38 -> 5.8156668 | L38: =+VLOOKUP(E38,Material!$H$2:$M$17,6,FALSE)*G38*H38*(1+Material!$K$14) -> 74.652013 | M38: =+Analisis!$J$5 -> T5.0 | N38: =+VLOOKUP(M38,Material!$A$3:$B$58,2,FALSE) -> 5000 | O38: ACERO A36 | P38: Cal 12 | Q38: =+IF(O38="ACERO A36",VLOOKUP(P38,'Velocidades Std 1500 w'!$B$2:$F$15,5,FALSE),IF(O38="INOXIDABLE",VLOOKUP(P38,'Velocidades Std 1500 w'!$B$17:$F$28,5,FALSE),IF(O38="ALUMINIO",VLOOKUP(P38,'Velocidades Std 1500 w'!$B$30:$F$38,5,FALSE)))) -> 4.3859649e-06 | R38: =+Q38*N38 -> 0.021929825 | S38: =+Q38*T38*3600 -> 33.216783 | T38: =(+H38*2+G38*2+V38*1.5)*25.4*1.05 -> 2103.7296 | U38: =+T38*R38 -> 46.134421 | V38: 10 | W38: =+IF(O38="ACERO A36",VLOOKUP(P38,'Tiempo Objeto'!$B$2:$C$12,2,FALSE),IF(O38="INOXIDABLE",VLOOKUP(P38,'Tiempo Objeto'!$B$14:$C$22,2,FALSE),IF(O38="ALUMINIO",VLOOKUP(P38,'Tiempo Objeto'!$B$24:$C$32,2,FALSE)))) -> 1.84 | X38: =+W38*V38 -> 18.4 | Y38: =+X38*N38/3600 -> 25.555556 | Z38: 0 | AA38: =30*Z38+Z38*$C38*1.5 -> 0 | AB38: =+Z38*Analisis!$J$6 -> 0 | AC38: 0 | AD38: =30*AC38+AC38*$C38*1.5 -> 0 | AE38: =+AD38*Analisis!$J$7 -> 0 | AF38: =+L38+U38+Y38+AB38+AE38 -> 146.34199 | AG38: =+AF38/(1-Analisis!$E$9) -> 182.92749 | AH38: =+AG38*C38 -> 0
B39: PP5309-74 MNT | C39: =IFERROR(VLOOKUP(B39,'REQ GALV'!A:B,2,0),0) -> 0 | D39: =+AG39 -> 94.966953 | E39: 12GA | F39: DECAPADO | G39: 17.5 | H39: 0.946 | I39: 0.105 | J39: 28.24 | K39: =+L39*2.2/J39 -> 0.95294165 | L39: =+VLOOKUP(E39,Material!$H$2:$M$17,6,FALSE)*G39*H39*(1+Material!$K$14) -> 12.232306 | M39: =+Analisis!$J$5 -> T5.0 | N39: =+VLOOKUP(M39,Material!$A$3:$B$58,2,FALSE) -> 5000 | O39: ACERO A36 | P39: Cal 12 | Q39: =+IF(O39="ACERO A36",VLOOKUP(P39,'Velocidades Std 1500 w'!$B$2:$F$15,5,FALSE),IF(O39="INOXIDABLE",VLOOKUP(P39,'Velocidades Std 1500 w'!$B$17:$F$28,5,FALSE),IF(O39="ALUMINIO",VLOOKUP(P39,'Velocidades Std 1500 w'!$B$30:$F$38,5,FALSE)))) -> 4.3859649e-06 | R39: =+Q39*N39 -> 0.021929825 | S39: =+Q39*T39*3600 -> 18.693705 | T39: =(+H39*2+G39*2+V39*1.5)*25.4*1.05 -> 1183.9346 | U39: =+T39*R39 -> 25.963479 | V39: 5 | W39: =+IF(O39="ACERO A36",VLOOKUP(P39,'Tiempo Objeto'!$B$2:$C$12,2,FALSE),IF(O39="INOXIDABLE",VLOOKUP(P39,'Tiempo Objeto'!$B$14:$C$22,2,FALSE),IF(O39="ALUMINIO",VLOOKUP(P39,'Tiempo Objeto'!$B$24:$C$32,2,FALSE)))) -> 1.84 | X39: =+W39*V39 -> 9.2 | Y39: =+X39*N39/3600 -> 12.777778 | Z39: 1 | AA39: =30*Z39+Z39*$C39*1.5 -> 30 | AB39: =+Z39*Analisis!$J$6 -> 25 | AC39: 0 | AD39: =30*AC39+AC39*$C39*1.5 -> 0 | AE39: =+AD39*Analisis!$J$7 -> 0 | AF39: =+L39+U39+Y39+AB39+AE39 -> 75.973562 | AG39: =+AF39/(1-Analisis!$E$9) -> 94.966953 | AH39: =+AG39*C39 -> 0
B40: 11-B-9366-01 MNT | C40: =IFERROR(VLOOKUP(B40,'REQ GALV'!A:B,2,0),0) -> 0 | D40: =+AG40 -> 1302.8949 | E40: 12GA | F40: DECAPADO | G40: 10.39 | H40: 91.56 | I40: 0.105 | J40: 28.24 | K40: =+L40*2.2/J40 -> 54.759372 | L40: =+VLOOKUP(E40,Material!$H$2:$M$17,6,FALSE)*G40*H40*(1+Material!$K$14) -> 702.91121 | M40: =+Analisis!$J$5 -> T5.0 | N40: =+VLOOKUP(M40,Material!$A$3:$B$58,2,FALSE) -> 5000 | O40: ACERO A36 | P40: Cal 12 | Q40: =+IF(O40="ACERO A36",VLOOKUP(P40,'Velocidades Std 1500 w'!$B$2:$F$15,5,FALSE),IF(O40="INOXIDABLE",VLOOKUP(P40,'Velocidades Std 1500 w'!$B$17:$F$28,5,FALSE),IF(O40="ALUMINIO",VLOOKUP(P40,'Velocidades Std 1500 w'!$B$30:$F$38,5,FALSE)))) -> 4.3859649e-06 | R40: =+Q40*N40 -> 0.021929825 | S40: =+Q40*T40*3600 -> 107.97139 | T40: =(+H40*2+G40*2+V40*1.5)*25.4*1.05 -> 6838.188 | U40: =+T40*R40 -> 149.96026 | V40: 35 | W40: =+IF(O40="ACERO A36",VLOOKUP(P40,'Tiempo Objeto'!$B$2:$C$12,2,FALSE),IF(O40="INOXIDABLE",VLOOKUP(P40,'Tiempo Objeto'!$B$14:$C$22,2,FALSE),IF(O40="ALUMINIO",VLOOKUP(P40,'Tiempo Objeto'!$B$24:$C$32,2,FALSE)))) -> 1.84 | X40: =+W40*V40 -> 64.4 | Y40: =+X40*N40/3600 -> 89.444444 | Z40: 4 | AA40: =30*Z40+Z40*$C40*1.5 -> 120 | AB40: =+Z40*Analisis!$J$6 -> 100 | AC40: 0 | AD40: =30*AC40+AC40*$C40*1.5 -> 0 | AE40: =+AD40*Analisis!$J$7 -> 0 | AF40: =+L40+U40+Y40+AB40+AE40 -> 1042.3159 | AG40: =+AF40/(1-Analisis!$E$9) -> 1302.8949 | AH40: =+AG40*C40 -> 0
B41: PP8886-46 MNT | C41: =IFERROR(VLOOKUP(B41,'REQ GALV'!A:B,2,0),0) -> 0 | D41: =+AG41 -> 87.146208 | E41: 12GA | F41: DECAPADO | G41: 3 | H41: 7.1 | I41: 0.105 | J41: 28.24 | K41: =+L41*2.2/J41 -> 1.2260741 | L41: =+VLOOKUP(E41,Material!$H$2:$M$17,6,FALSE)*G41*H41*(1+Material!$K$14) -> 15.738333 | M41: =+Analisis!$J$5 -> T5.0 | N41: =+VLOOKUP(M41,Material!$A$3:$B$58,2,FALSE) -> 5000 | O41: ACERO A36 | P41: Cal 12 | Q41: =+IF(O41="ACERO A36",VLOOKUP(P41,'Velocidades Std 1500 w'!$B$2:$F$15,5,FALSE),IF(O41="INOXIDABLE",VLOOKUP(P41,'Velocidades Std 1500 w'!$B$17:$F$28,5,FALSE),IF(O41="ALUMINIO",VLOOKUP(P41,'Velocidades Std 1500 w'!$B$30:$F$38,5,FALSE)))) -> 4.3859649e-06 | R41: =+Q41*N41 -> 0.021929825 | S41: =+Q41*T41*3600 -> 11.664616 | T41: =(+H41*2+G41*2+V41*1.5)*25.4*1.05 -> 738.759 | U41: =+T41*R41 -> 16.200855 | V41: 5 | W41: =+IF(O41="ACERO A36",VLOOKUP(P41,'Tiempo Objeto'!$B$2:$C$12,2,FALSE),IF(O41="INOXIDABLE",VLOOKUP(P41,'Tiempo Objeto'!$B$14:$C$22,2,FALSE),IF(O41="ALUMINIO",VLOOKUP(P41,'Tiempo Objeto'!$B$24:$C$32,2,FALSE)))) -> 1.84 | X41: =+W41*V41 -> 9.2 | Y41: =+X41*N41/3600 -> 12.777778 | Z41: 1 | AA41: =30*Z41+Z41*$C41*1.5 -> 30 | AB41: =+Z41*Analisis!$J$6 -> 25 | AC41: 0 | AD41: =30*AC41+AC41*$C41*1.5 -> 0 | AE41: =+AD41*Analisis!$J$7 -> 0 | AF41: =+L41+U41+Y41+AB41+AE41 -> 69.716966 | AG41: =+AF41/(1-Analisis!$E$9) -> 87.146208 | AH41: =+AG41*C41 -> 0
B42: PP9616-783 MNT1 | C42: =IFERROR(VLOOKUP(B42,'REQ GALV'!A:B,2,0),0) -> 0 | D42: =+AG42 -> 709.38619 | E42: 12GA | F42: DECAPADO | G42: 15.525 | H42: 27.4 | I42: 0.105 | J42: 28.24 | K42: =+L42*2.2/J42 -> 24.486082 | L42: =+VLOOKUP(E42,Material!$H$2:$M$17,6,FALSE)*G42*H42*(1+Material!$K$14) -> 314.31225 | M42: =+Analisis!$J$5 -> T5.0 | N42: =+VLOOKUP(M42,Material!$A$3:$B$58,2,FALSE) -> 5000 | O42: ACERO A36 | P42: Cal 12 | Q42: =+IF(O42="ACERO A36",VLOOKUP(P42,'Velocidades Std 1500 w'!$B$2:$F$15,5,FALSE),IF(O42="INOXIDABLE",VLOOKUP(P42,'Velocidades Std 1500 w'!$B$17:$F$28,5,FALSE),IF(O42="ALUMINIO",VLOOKUP(P42,'Velocidades Std 1500 w'!$B$30:$F$38,5,FALSE)))) -> 4.3859649e-06 | R42: =+Q42*N42 -> 0.021929825 | S42: =+Q42*T42*3600 -> 55.101624 | T42: =(+H42*2+G42*2+V42*1.5)*25.4*1.05 -> 3489.7695 | U42: =+T42*R42 -> 76.530033 | V42: 30 | W42: =+IF(O42="ACERO A36",VLOOKUP(P42,'Tiempo Objeto'!$B$2:$C$12,2,FALSE),IF(O42="INOXIDABLE",VLOOKUP(P42,'Tiempo Objeto'!$B$14:$C$22,2,FALSE),IF(O42="ALUMINIO",VLOOKUP(P42,'Tiempo Objeto'!$B$24:$C$32,2,FALSE)))) -> 1.84 | X42: =+W42*V42 -> 55.2 | Y42: =+X42*N42/3600 -> 76.666667 | Z42: 4 | AA42: =30*Z42+Z42*$C42*1.5 -> 120 | AB42: =+Z42*Analisis!$J$6 -> 100 | AC42: 0 | AD42: =30*AC42+AC42*$C42*1.5 -> 0 | AE42: =+AD42*Analisis!$J$7 -> 0 | AF42: =+L42+U42+Y42+AB42+AE42 -> 567.50895 | AG42: =+AF42/(1-Analisis!$E$9) -> 709.38619 | AH42: =+AG42*C42 -> 0
B43: PP9616-801 | C43: =IFERROR(VLOOKUP(B43,'REQ GALV'!A:B,2,0),0) -> 0 | D43: =+AG43 -> 191.51965 | E43: 12GA | F43: DECAPADO | G43: 4.39 | H43: 7.005 | I43: 0.105 | J43: 28.24 | K43: =+L43*2.2/J43 -> 1.7701488 | L43: =+VLOOKUP(E43,Material!$H$2:$M$17,6,FALSE)*G43*H43*(1+Material!$K$14) -> 22.722274 | M43: =+Analisis!$J$5 -> T5.0 | N43: =+VLOOKUP(M43,Material!$A$3:$B$58,2,FALSE) -> 5000 | O43: ACERO A36 | P43: Cal 12 | Q43: =+IF(O43="ACERO A36",VLOOKUP(P43,'Velocidades Std 1500 w'!$B$2:$F$15,5,FALSE),IF(O43="INOXIDABLE",VLOOKUP(P43,'Velocidades Std 1500 w'!$B$17:$F$28,5,FALSE),IF(O43="ALUMINIO",VLOOKUP(P43,'Velocidades Std 1500 w'!$B$30:$F$38,5,FALSE)))) -> 4.3859649e-06 | R43: =+Q43*N43 -> 0.021929825 | S43: =+Q43*T43*3600 -> 12.755278 | T43: =(+H43*2+G43*2+V43*1.5)*25.4*1.05 -> 807.8343 | U43: =+T43*R43 -> 17.715664 | V43: 5 | W43: =+IF(O43="ACERO A36",VLOOKUP(P43,'Tiempo Objeto'!$B$2:$C$12,2,FALSE),IF(O43="INOXIDABLE",VLOOKUP(P43,'Tiempo Objeto'!$B$14:$C$22,2,FALSE),IF(O43="ALUMINIO",VLOOKUP(P43,'Tiempo Objeto'!$B$24:$C$32,2,FALSE)))) -> 1.84 | X43: =+W43*V43 -> 9.2 | Y43: =+X43*N43/3600 -> 12.777778 | Z43: 4 | AA43: =30*Z43+Z43*$C43*1.5 -> 120 | AB43: =+Z43*Analisis!$J$6 -> 100 | AC43: 0 | AD43: =30*AC43+AC43*$C43*1.5 -> 0 | AE43: =+AD43*Analisis!$J$7 -> 0 | AF43: =+L43+U43+Y43+AB43+AE43 -> 153.21572 | AG43: =+AF43/(1-Analisis!$E$9) -> 191.51965 | AH43: =+AG43*C43 -> 0
B44: P8533-59 | C44: =IFERROR(VLOOKUP(B44,'REQ GALV'!A:B,2,0),0) -> 0 | D44: =+AG44 -> 56.569786 | E44: 12GA | F44: DECAPADO | G44: 1.75 | H44: 1.818 | I44: 0.105 | J44: 28.24 | K44: =+L44*2.2/J44 -> 0.18313403 | L44: =+VLOOKUP(E44,Material!$H$2:$M$17,6,FALSE)*G44*H44*(1+Material!$K$14) -> 2.350775 | M44: =+Analisis!$J$5 -> T5.0 | N44: =+VLOOKUP(M44,Material!$A$3:$B$58,2,FALSE) -> 5000 | O44: ACERO A36 | P44: Cal 12 | Q44: =+IF(O44="ACERO A36",VLOOKUP(P44,'Velocidades Std 1500 w'!$B$2:$F$15,5,FALSE),IF(O44="INOXIDABLE",VLOOKUP(P44,'Velocidades Std 1500 w'!$B$17:$F$28,5,FALSE),IF(O44="ALUMINIO",VLOOKUP(P44,'Velocidades Std 1500 w'!$B$30:$F$38,5,FALSE)))) -> 4.3859649e-06 | R44: =+Q44*N44 -> 0.021929825 | S44: =+Q44*T44*3600 -> 5.5316387 | T44: =(+H44*2+G44*2+V44*1.5)*25.4*1.05 -> 350.33712 | U44: =+T44*R44 -> 7.6828316 | V44: 4 | W44: =+IF(O44="ACERO A36",VLOOKUP(P44,'Tiempo Objeto'!$B$2:$C$12,2,FALSE),IF(O44="INOXIDABLE",VLOOKUP(P44,'Tiempo Objeto'!$B$14:$C$22,2,FALSE),IF(O44="ALUMINIO",VLOOKUP(P44,'Tiempo Objeto'!$B$24:$C$32,2,FALSE)))) -> 1.84 | X44: =+W44*V44 -> 7.36 | Y44: =+X44*N44/3600 -> 10.222222 | Z44: 1 | AA44: =30*Z44+Z44*$C44*1.5 -> 30 | AB44: =+Z44*Analisis!$J$6 -> 25 | AC44: 0 | AD44: =30*AC44+AC44*$C44*1.5 -> 0 | AE44: =+AD44*Analisis!$J$7 -> 0 | AF44: =+L44+U44+Y44+AB44+AE44 -> 45.255829 | AG44: =+AF44/(1-Analisis!$E$9) -> 56.569786 | AH44: =+AG44*C44 -> 0
B45: DS-A-22000 | C45: =IFERROR(VLOOKUP(B45,'REQ GALV'!A:B,2,0),0) -> 0 | D45: =+AG45 -> 747.56517 | E45: 12GA | F45: DECAPADO | G45: 22.12 | H45: 25 | I45: 0.105 | J45: 28.24 | K45: =+L45*2.2/J45 -> 31.831878 | L45: =+VLOOKUP(E45,Material!$H$2:$M$17,6,FALSE)*G45*H45*(1+Material!$K$14) -> 408.60556 | M45: =+Analisis!$J$5 -> T5.0 | N45: =+VLOOKUP(M45,Material!$A$3:$B$58,2,FALSE) -> 5000 | O45: ACERO A36 | P45: Cal 12 | Q45: =+IF(O45="ACERO A36",VLOOKUP(P45,'Velocidades Std 1500 w'!$B$2:$F$15,5,FALSE),IF(O45="INOXIDABLE",VLOOKUP(P45,'Velocidades Std 1500 w'!$B$17:$F$28,5,FALSE),IF(O45="ALUMINIO",VLOOKUP(P45,'Velocidades Std 1500 w'!$B$30:$F$38,5,FALSE)))) -> 4.3859649e-06 | R45: =+Q45*N45 -> 0.021929825 | S45: =+Q45*T45*3600 -> 46.001539 | T45: =(+H45*2+G45*2+V45*1.5)*25.4*1.05 -> 2913.4308 | U45: =+T45*R45 -> 63.891026 | V45: 10 | W45: =+IF(O45="ACERO A36",VLOOKUP(P45,'Tiempo Objeto'!$B$2:$C$12,2,FALSE),IF(O45="INOXIDABLE",VLOOKUP(P45,'Tiempo Objeto'!$B$14:$C$22,2,FALSE),IF(O45="ALUMINIO",VLOOKUP(P45,'Tiempo Objeto'!$B$24:$C$32,2,FALSE)))) -> 1.84 | X45: =+W45*V45 -> 18.4 | Y45: =+X45*N45/3600 -> 25.555556 | Z45: 4 | AA45: =30*Z45+Z45*$C45*1.5 -> 120 | AB45: =+Z45*Analisis!$J$6 -> 100 | AC45: 0 | AD45: =30*AC45+AC45*$C45*1.5 -> 0 | AE45: =+AD45*Analisis!$J$7 -> 0 | AF45: =+L45+U45+Y45+AB45+AE45 -> 598.05214 | AG45: =+AF45/(1-Analisis!$E$9) -> 747.56517 | AH45: =+AG45*C45 -> 0
B46: PP8886-46 MNT1 | C46: =IFERROR(VLOOKUP(B46,'REQ GALV'!A:B,2,0),0) -> 0 | D46: =+AG46 -> 90.109311 | E46: 12GA | F46: DECAPADO | G46: 3 | H46: 7.8 | I46: 0.105 | J46: 28.24 | K46: =+L46*2.2/J46 -> 1.3469547 | L46: =+VLOOKUP(E46,Material!$H$2:$M$17,6,FALSE)*G46*H46*(1+Material!$K$14) -> 17.29 | M46: =+Analisis!$J$5 -> T5.0 | N46: =+VLOOKUP(M46,Material!$A$3:$B$58,2,FALSE) -> 5000 | O46: ACERO A36 | P46: Cal 12 | Q46: =+IF(O46="ACERO A36",VLOOKUP(P46,'Velocidades Std 1500 w'!$B$2:$F$15,5,FALSE),IF(O46="INOXIDABLE",VLOOKUP(P46,'Velocidades Std 1500 w'!$B$17:$F$28,5,FALSE),IF(O46="ALUMINIO",VLOOKUP(P46,'Velocidades Std 1500 w'!$B$30:$F$38,5,FALSE)))) -> 4.3859649e-06 | R46: =+Q46*N46 -> 0.021929825 | S46: =+Q46*T46*3600 -> 12.254163 | T46: =(+H46*2+G46*2+V46*1.5)*25.4*1.05 -> 776.097 | U46: =+T46*R46 -> 17.019671 | V46: 5 | W46: =+IF(O46="ACERO A36",VLOOKUP(P46,'Tiempo Objeto'!$B$2:$C$12,2,FALSE),IF(O46="INOXIDABLE",VLOOKUP(P46,'Tiempo Objeto'!$B$14:$C$22,2,FALSE),IF(O46="ALUMINIO",VLOOKUP(P46,'Tiempo Objeto'!$B$24:$C$32,2,FALSE)))) -> 1.84 | X46: =+W46*V46 -> 9.2 | Y46: =+X46*N46/3600 -> 12.777778 | Z46: 1 | AA46: =30*Z46+Z46*$C46*1.5 -> 30 | AB46: =+Z46*Analisis!$J$6 -> 25 | AC46: 0 | AD46: =30*AC46+AC46*$C46*1.5 -> 0 | AE46: =+AD46*Analisis!$J$7 -> 0 | AF46: =+L46+U46+Y46+AB46+AE46 -> 72.087449 | AG46: =+AF46/(1-Analisis!$E$9) -> 90.109311 | AH46: =+AG46*C46 -> 0
B47: PP9616-783 MNT2 | C47: =IFERROR(VLOOKUP(B47,'REQ GALV'!A:B,2,0),0) -> 0 | D47: =+AG47 -> 641.79417 | E47: 12GA | F47: DECAPADO | G47: 13 | H47: 27.4 | I47: 0.105 | J47: 28.24 | K47: =+L47*2.2/J47 -> 20.503643 | L47: =+VLOOKUP(E47,Material!$H$2:$M$17,6,FALSE)*G47*H47*(1+Material!$K$14) -> 263.19222 | M47: =+Analisis!$J$5 -> T5.0 | N47: =+VLOOKUP(M47,Material!$A$3:$B$58,2,FALSE) -> 5000 | O47: ACERO A36 | P47: Cal 12 | Q47: =+IF(O47="ACERO A36",VLOOKUP(P47,'Velocidades Std 1500 w'!$B$2:$F$15,5,FALSE),IF(O47="INOXIDABLE",VLOOKUP(P47,'Velocidades Std 1500 w'!$B$17:$F$28,5,FALSE),IF(O47="ALUMINIO",VLOOKUP(P47,'Velocidades Std 1500 w'!$B$30:$F$38,5,FALSE)))) -> 4.3859649e-06 | R47: =+Q47*N47 -> 0.021929825 | S47: =+Q47*T47*3600 -> 52.975042 | T47: =(+H47*2+G47*2+V47*1.5)*25.4*1.05 -> 3355.086 | U47: =+T47*R47 -> 73.576447 | V47: 30 | W47: =+IF(O47="ACERO A36",VLOOKUP(P47,'Tiempo Objeto'!$B$2:$C$12,2,FALSE),IF(O47="INOXIDABLE",VLOOKUP(P47,'Tiempo Objeto'!$B$14:$C$22,2,FALSE),IF(O47="ALUMINIO",VLOOKUP(P47,'Tiempo Objeto'!$B$24:$C$32,2,FALSE)))) -> 1.84 | X47: =+W47*V47 -> 55.2 | Y47: =+X47*N47/3600 -> 76.666667 | Z47: 4 | AA47: =30*Z47+Z47*$C47*1.5 -> 120 | AB47: =+Z47*Analisis!$J$6 -> 100 | AC47: 0 | AD47: =30*AC47+AC47*$C47*1.5 -> 0 | AE47: =+AD47*Analisis!$J$7 -> 0 | AF47: =+L47+U47+Y47+AB47+AE47 -> 513.43534 | AG47: =+AF47/(1-Analisis!$E$9) -> 641.79417 | AH47: =+AG47*C47 -> 0
B48: 11-C-9662-01 | C48: =IFERROR(VLOOKUP(B48,'REQ GALV'!A:B,2,0),0) -> 0 | D48: =+AG48 -> 228.94505 | E48: 12GA | F48: DECAPADO | G48: 8.57 | H48: 17 | I48: 0.105 | J48: 28.24 | K48: =+L48*2.2/J48 -> 8.3862319 | L48: =+VLOOKUP(E48,Material!$H$2:$M$17,6,FALSE)*G48*H48*(1+Material!$K$14) -> 107.64872 | M48: =+Analisis!$J$5 -> T5.0 | N48: =+VLOOKUP(M48,Material!$A$3:$B$58,2,FALSE) -> 5000 | O48: ACERO A36 | P48: Cal 12 | Q48: =+IF(O48="ACERO A36",VLOOKUP(P48,'Velocidades Std 1500 w'!$B$2:$F$15,5,FALSE),IF(O48="INOXIDABLE",VLOOKUP(P48,'Velocidades Std 1500 w'!$B$17:$F$28,5,FALSE),IF(O48="ALUMINIO",VLOOKUP(P48,'Velocidades Std 1500 w'!$B$30:$F$38,5,FALSE)))) -> 4.3859649e-06 | R48: =+Q48*N48 -> 0.021929825 | S48: =+Q48*T48*3600 -> 25.325271 | T48: =(+H48*2+G48*2+V48*1.5)*25.4*1.05 -> 1603.9338 | U48: =+T48*R48 -> 35.173987 | V48: 6 | W48: =+IF(O48="ACERO A36",VLOOKUP(P48,'Tiempo Objeto'!$B$2:$C$12,2,FALSE),IF(O48="INOXIDABLE",VLOOKUP(P48,'Tiempo Objeto'!$B$14:$C$22,2,FALSE),IF(O48="ALUMINIO",VLOOKUP(P48,'Tiempo Objeto'!$B$24:$C$32,2,FALSE)))) -> 1.84 | X48: =+W48*V48 -> 11.04 | Y48: =+X48*N48/3600 -> 15.333333 | Z48: 1 | AA48: =30*Z48+Z48*$C48*1.5 -> 30 | AB48: =+Z48*Analisis!$J$6 -> 25 | AC48: 0 | AD48: =30*AC48+AC48*$C48*1.5 -> 0 | AE48: =+AD48*Analisis!$J$7 -> 0 | AF48: =+L48+U48+Y48+AB48+AE48 -> 183.15604 | AG48: =+AF48/(1-Analisis!$E$9) -> 228.94505 | AH48: =+AG48*C48 -> 0
B49: 11-C-9662-02 | C49: =IFERROR(VLOOKUP(B49,'REQ GALV'!A:B,2,0),0) -> 0 | D49: =+AG49 -> 322.72024 | E49: 12GA | F49: DECAPADO | G49: 8.57 | H49: 27 | I49: 0.105 | J49: 28.24 | K49: =+L49*2.2/J49 -> 13.319309 | L49: =+VLOOKUP(E49,Material!$H$2:$M$17,6,FALSE)*G49*H49*(1+Material!$K$14) -> 170.9715 | M49: =+Analisis!$J$5 -> T5.0 | N49: =+VLOOKUP(M49,Material!$A$3:$B$58,2,FALSE) -> 5000 | O49: ACERO A36 | P49: Cal 12 | Q49: =+IF(O49="ACERO A36",VLOOKUP(P49,'Velocidades Std 1500 w'!$B$2:$F$15,5,FALSE),IF(O49="INOXIDABLE",VLOOKUP(P49,'Velocidades Std 1500 w'!$B$17:$F$28,5,FALSE),IF(O49="ALUMINIO",VLOOKUP(P49,'Velocidades Std 1500 w'!$B$30:$F$38,5,FALSE)))) -> 4.3859649e-06 | R49: =+Q49*N49 -> 0.021929825 | S49: =+Q49*T49*3600 -> 33.747376 | T49: =(+H49*2+G49*2+V49*1.5)*25.4*1.05 -> 2137.3338 | U49: =+T49*R49 -> 46.871355 | V49: 6 | W49: =+IF(O49="ACERO A36",VLOOKUP(P49,'Tiempo Objeto'!$B$2:$C$12,2,FALSE),IF(O49="INOXIDABLE",VLOOKUP(P49,'Tiempo Objeto'!$B$14:$C$22,2,FALSE),IF(O49="ALUMINIO",VLOOKUP(P49,'Tiempo Objeto'!$B$24:$C$32,2,FALSE)))) -> 1.84 | X49: =+W49*V49 -> 11.04 | Y49: =+X49*N49/3600 -> 15.333333 | Z49: 1 | AA49: =30*Z49+Z49*$C49*1.5 -> 30 | AB49: =+Z49*Analisis!$J$6 -> 25 | AC49: 0 | AD49: =30*AC49+AC49*$C49*1.5 -> 0 | AE49: =+AD49*Analisis!$J$7 -> 0 | AF49: =+L49+U49+Y49+AB49+AE49 -> 258.17619 | AG49: =+AF49/(1-Analisis!$E$9) -> 322.72024 | AH49: =+AG49*C49 -> 0
B50: 11-C-9662-03 | C50: =IFERROR(VLOOKUP(B50,'REQ GALV'!A:B,2,0),0) -> 0 | D50: =+AG50 -> 416.49542 | E50: 12GA | F50: DECAPADO | G50: 8.57 | H50: 37 | I50: 0.105 | J50: 28.24 | K50: =+L50*2.2/J50 -> 18.252387 | L50: =+VLOOKUP(E50,Material!$H$2:$M$17,6,FALSE)*G50*H50*(1+Material!$K$14) -> 234.29428 | M50: =+Analisis!$J$5 -> T5.0 | N50: =+VLOOKUP(M50,Material!$A$3:$B$58,2,FALSE) -> 5000 | O50: ACERO A36 | P50: Cal 12 | Q50: =+IF(O50="ACERO A36",VLOOKUP(P50,'Velocidades Std 1500 w'!$B$2:$F$15,5,FALSE),IF(O50="INOXIDABLE",VLOOKUP(P50,'Velocidades Std 1500 w'!$B$17:$F$28,5,FALSE),IF(O50="ALUMINIO",VLOOKUP(P50,'Velocidades Std 1500 w'!$B$30:$F$38,5,FALSE)))) -> 4.3859649e-06 | R50: =+Q50*N50 -> 0.021929825 | S50: =+Q50*T50*3600 -> 42.169481 | T50: =(+H50*2+G50*2+V50*1.5)*25.4*1.05 -> 2670.7338 | U50: =+T50*R50 -> 58.568724 | V50: 6 | W50: =+IF(O50="ACERO A36",VLOOKUP(P50,'Tiempo Objeto'!$B$2:$C$12,2,FALSE),IF(O50="INOXIDABLE",VLOOKUP(P50,'Tiempo Objeto'!$B$14:$C$22,2,FALSE),IF(O50="ALUMINIO",VLOOKUP(P50,'Tiempo Objeto'!$B$24:$C$32,2,FALSE)))) -> 1.84 | X50: =+W50*V50 -> 11.04 | Y50: =+X50*N50/3600 -> 15.333333 | Z50: 1 | AA50: =30*Z50+Z50*$C50*1.5 -> 30 | AB50: =+Z50*Analisis!$J$6 -> 25 | AC50: 0 | AD50: =30*AC50+AC50*$C50*1.5 -> 0 | AE50: =+AD50*Analisis!$J$7 -> 0 | AF50: =+L50+U50+Y50+AB50+AE50 -> 333.19633 | AG50: =+AF50/(1-Analisis!$E$9) -> 416.49542 | AH50: =+AG50*C50 -> 0
... B146: PP14252-17 | C146: =IFERROR(VLOOKUP(B146,'REQ GALV'!A:B,2,0),0) -> 0 | D146: =+AG146 -> 530.00977 | E146: 188al | F146: DECAPADO | G146: 5.048 | H146: 39.92 | I146: 0.105 | J146: 28.24 | K146: =+L146*2.2/J146 -> 17.39956 | L146: =+VLOOKUP(E146,Material!$H$2:$M$17,6,FALSE)*G146*H146*(1+Material!$K$14) -> 223.34708 | M146: =+Analisis!$J$5 -> T5.0 | N146: =+VLOOKUP(M146,Material!$A$3:$B$58,2,FALSE) -> 5000 | O146: ACERO A36 | P146: Cal 12 | Q146: =+IF(O146="ACERO A36",VLOOKUP(P146,'Velocidades Std 1500 w'!$B$2:$F$15,5,FALSE),IF(O146="INOXIDABLE",VLOOKUP(P146,'Velocidades Std 1500 w'!$B$17:$F$28,5,FALSE),IF(O146="ALUMINIO",VLOOKUP(P146,'Velocidades Std 1500 w'!$B$30:$F$38,5,FALSE)))) -> 4.3859649e-06 | R146: =+Q146*N146 -> 0.021929825 | S146: =+Q146*T146*3600 -> 46.715733 | T146: =(+H146*2+G146*2+V146*1.5)*25.4*1.05 -> 2958.6631 | U146: =+T146*R146 -> 64.882963 | V146: 14 | W146: =+IF(O146="ACERO A36",VLOOKUP(P146,'Tiempo Objeto'!$B$2:$C$12,2,FALSE),IF(O146="INOXIDABLE",VLOOKUP(P146,'Tiempo Objeto'!$B$14:$C$22,2,FALSE),IF(O146="ALUMINIO",VLOOKUP(P146,'Tiempo Objeto'!$B$24:$C$32,2,FALSE)))) -> 1.84 | X146: =+W146*V146 -> 25.76 | Y146: =+X146*N146/3600 -> 35.777778 | Z146: 4 | AA146: =30*Z146+Z146*$C146*1.5 -> 120 | AB146: =+Z146*Analisis!$J$6 -> 100 | AC146: 0 | AD146: =30*AC146+AC146*$C146*1.5 -> 0 | AE146: =+AD146*Analisis!$J$7 -> 0 | AF146: =+L146+U146+Y146+AB146+AE146 -> 424.00782 | AG146: =+AF146/(1-Analisis!$E$9) -> 530.00977 | AH146: =+AG146*C146 -> 0
B147: 11-6284-01 | C147: =IFERROR(VLOOKUP(B147,'REQ GALV'!A:B,2,0),0) -> 210 | D147: =+AG147 -> 188.10087 | E147: 12ga | F147: DECAPADO | G147: 6.64 | H147: 3.64 | I147: 0.105 | J147: 28.24 | K147: =+L147*2.2/J147 -> 1.3912545 | L147: =+VLOOKUP(E147,Material!$H$2:$M$17,6,FALSE)*G147*H147*(1+Material!$K$14) -> 17.858649 | M147: =+Analisis!$J$5 -> T5.0 | N147: =+VLOOKUP(M147,Material!$A$3:$B$58,2,FALSE) -> 5000 | O147: ACERO A36 | P147: Cal 12 | Q147: =+IF(O147="ACERO A36",VLOOKUP(P147,'Velocidades Std 1500 w'!$B$2:$F$15,5,FALSE),IF(O147="INOXIDABLE",VLOOKUP(P147,'Velocidades Std 1500 w'!$B$17:$F$28,5,FALSE),IF(O147="ALUMINIO",VLOOKUP(P147,'Velocidades Std 1500 w'!$B$30:$F$38,5,FALSE)))) -> 4.3859649e-06 | R147: =+Q147*N147 -> 0.021929825 | S147: =+Q147*T147*3600 -> 12.447872 | T147: =(+H147*2+G147*2+V147*1.5)*25.4*1.05 -> 788.3652 | U147: =+T147*R147 -> 17.288711 | V147: 6 | W147: =+IF(O147="ACERO A36",VLOOKUP(P147,'Tiempo Objeto'!$B$2:$C$12,2,FALSE),IF(O147="INOXIDABLE",VLOOKUP(P147,'Tiempo Objeto'!$B$14:$C$22,2,FALSE),IF(O147="ALUMINIO",VLOOKUP(P147,'Tiempo Objeto'!$B$24:$C$32,2,FALSE)))) -> 1.84 | X147: =+W147*V147 -> 11.04 | Y147: =+X147*N147/3600 -> 15.333333 | Z147: 4 | AA147: =30*Z147+Z147*$C147*1.5 -> 1380 | AB147: =+Z147*Analisis!$J$6 -> 100 | AC147: 0 | AD147: =30*AC147+AC147*$C147*1.5 -> 0 | AE147: =+AD147*Analisis!$J$7 -> 0 | AF147: =+L147+U147+Y147+AB147+AE147 -> 150.48069 | AG147: =+AF147/(1-Analisis!$E$9) -> 188.10087 | AH147: =+AG147*C147 -> 39501.182 | AI147: =+L147*C147 -> 3750.3163
B148: 11-8233-01 | C148: =IFERROR(VLOOKUP(B148,'REQ GALV'!A:B,2,0),0) -> 0 | D148: =+AG148 -> 125.55262 | E148: 12ga | F148: DECAPADO | G148: 3.64 | H148: 6.63 | I148: 0.105 | J148: 28.24 | K148: =+L148*2.2/J148 -> 1.3891593 | L148: =+VLOOKUP(E148,Material!$H$2:$M$17,6,FALSE)*G148*H148*(1+Material!$K$14) -> 17.831753 | M148: =+Analisis!$J$5 -> T5.0 | N148: =+VLOOKUP(M148,Material!$A$3:$B$58,2,FALSE) -> 5000 | O148: ACERO A36 | P148: Cal 12 | Q148: =+IF(O148="ACERO A36",VLOOKUP(P148,'Velocidades Std 1500 w'!$B$2:$F$15,5,FALSE),IF(O148="INOXIDABLE",VLOOKUP(P148,'Velocidades Std 1500 w'!$B$17:$F$28,5,FALSE),IF(O148="ALUMINIO",VLOOKUP(P148,'Velocidades Std 1500 w'!$B$30:$F$38,5,FALSE)))) -> 4.3859649e-06 | R148: =+Q148*N148 -> 0.021929825 | S148: =+Q148*T148*3600 -> 12.439449 | T148: =(+H148*2+G148*2+V148*1.5)*25.4*1.05 -> 787.8318 | U148: =+T148*R148 -> 17.277013 | V148: 6 | W148: =+IF(O148="ACERO A36",VLOOKUP(P148,'Tiempo Objeto'!$B$2:$C$12,2,FALSE),IF(O148="INOXIDABLE",VLOOKUP(P148,'Tiempo Objeto'!$B$14:$C$22,2,FALSE),IF(O148="ALUMINIO",VLOOKUP(P148,'Tiempo Objeto'!$B$24:$C$32,2,FALSE)))) -> 1.84 | X148: =+W148*V148 -> 11.04 | Y148: =+X148*N148/3600 -> 15.333333 | Z148: 2 | AA148: =30*Z148+Z148*$C148*1.5 -> 60 | AB148: =+Z148*Analisis!$J$6 -> 50 | AC148: 0 | AD148: =30*AC148+AC148*$C148*1.5 -> 0 | AE148: =+AD148*Analisis!$J$7 -> 0 | AF148: =+L148+U148+Y148+AB148+AE148 -> 100.4421 | AG148: =+AF148/(1-Analisis!$E$9) -> 125.55262 | AH148: =+AG148*C148 -> 0
B149: 11-A-6030-01 | C149: =IFERROR(VLOOKUP(B149,'REQ GALV'!A:B,2,0),0) -> 0 | D149: =+AG149 -> 29.818249 | E149: 12ga | F149: DECAPADO | G149: 2 | H149: 2.94 | I149: 0.105 | J149: 28.24 | K149: =+L149*2.2/J149 -> 0.33846553 | L149: =+VLOOKUP(E149,Material!$H$2:$M$17,6,FALSE)*G149*H149*(1+Material!$K$14) -> 4.3446667 | M149: =+Analisis!$J$5 -> T5.0 | N149: =+VLOOKUP(M149,Material!$A$3:$B$58,2,FALSE) -> 5000 | O149: ACERO A36 | P149: Cal 12 | Q149: =+IF(O149="ACERO A36",VLOOKUP(P149,'Velocidades Std 1500 w'!$B$2:$F$15,5,FALSE),IF(O149="INOXIDABLE",VLOOKUP(P149,'Velocidades Std 1500 w'!$B$17:$F$28,5,FALSE),IF(O149="ALUMINIO",VLOOKUP(P149,'Velocidades Std 1500 w'!$B$30:$F$38,5,FALSE)))) -> 4.3859649e-06 | R149: =+Q149*N149 -> 0.021929825 | S149: =+Q149*T149*3600 -> 6.6871516 | T149: =(+H149*2+G149*2+V149*1.5)*25.4*1.05 -> 423.5196 | U149: =+T149*R149 -> 9.2877105 | V149: 4 | W149: =+IF(O149="ACERO A36",VLOOKUP(P149,'Tiempo Objeto'!$B$2:$C$12,2,FALSE),IF(O149="INOXIDABLE",VLOOKUP(P149,'Tiempo Objeto'!$B$14:$C$22,2,FALSE),IF(O149="ALUMINIO",VLOOKUP(P149,'Tiempo Objeto'!$B$24:$C$32,2,FALSE)))) -> 1.84 | X149: =+W149*V149 -> 7.36 | Y149: =+X149*N149/3600 -> 10.222222 | Z149: 0 | AA149: =30*Z149+Z149*$C149*1.5 -> 0 | AB149: =+Z149*Analisis!$J$6 -> 0 | AC149: 0 | AD149: =30*AC149+AC149*$C149*1.5 -> 0 | AE149: =+AD149*Analisis!$J$7 -> 0 | AF149: =+L149+U149+Y149+AB149+AE149 -> 23.854599 | AG149: =+AF149/(1-Analisis!$E$9) -> 29.818249 | AH149: =+AG149*C149 -> 0
B150: 11-A-6030-02 | C150: =IFERROR(VLOOKUP(B150,'REQ GALV'!A:B,2,0),0) -> 0 | D150: =+AG150 -> 27.534768 | E150: 12ga | F150: DECAPADO | G150: 2 | H150: 2.25 | I150: 0.105 | J150: 28.24 | K150: =+L150*2.2/J150 -> 0.25902975 | L150: =+VLOOKUP(E150,Material!$H$2:$M$17,6,FALSE)*G150*H150*(1+Material!$K$14) -> 3.325 | M150: =+Analisis!$J$5 -> T5.0 | N150: =+VLOOKUP(M150,Material!$A$3:$B$58,2,FALSE) -> 5000 | O150: ACERO A36 | P150: Cal 12 | Q150: =+IF(O150="ACERO A36",VLOOKUP(P150,'Velocidades Std 1500 w'!$B$2:$F$15,5,FALSE),IF(O150="INOXIDABLE",VLOOKUP(P150,'Velocidades Std 1500 w'!$B$17:$F$28,5,FALSE),IF(O150="ALUMINIO",VLOOKUP(P150,'Velocidades Std 1500 w'!$B$30:$F$38,5,FALSE)))) -> 4.3859649e-06 | R150: =+Q150*N150 -> 0.021929825 | S150: =+Q150*T150*3600 -> 6.1060263 | T150: =(+H150*2+G150*2+V150*1.5)*25.4*1.05 -> 386.715 | U150: =+T150*R150 -> 8.4805921 | V150: 4 | W150: =+IF(O150="ACERO A36",VLOOKUP(P150,'Tiempo Objeto'!$B$2:$C$12,2,FALSE),IF(O150="INOXIDABLE",VLOOKUP(P150,'Tiempo Objeto'!$B$14:$C$22,2,FALSE),IF(O150="ALUMINIO",VLOOKUP(P150,'Tiempo Objeto'!$B$24:$C$32,2,FALSE)))) -> 1.84 | X150: =+W150*V150 -> 7.36 | Y150: =+X150*N150/3600 -> 10.222222 | Z150: 0 | AA150: =30*Z150+Z150*$C150*1.5 -> 0 | AB150: =+Z150*Analisis!$J$6 -> 0 | AC150: 0 | AD150: =30*AC150+AC150*$C150*1.5 -> 0 | AE150: =+AD150*Analisis!$J$7 -> 0 | AF150: =+L150+U150+Y150+AB150+AE150 -> 22.027814 | AG150: =+AF150/(1-Analisis!$E$9) -> 27.534768 | AH150: =+AG150*C150 -> 0
B151: 11-A-6030-03 | C151: =IFERROR(VLOOKUP(B151,'REQ GALV'!A:B,2,0),0) -> 0 | D151: =+AG151 -> 34.782339 | E151: 12ga | F151: DECAPADO | G151: 2 | H151: 4.44 | I151: 0.105 | J151: 28.24 | K151: =+L151*2.2/J151 -> 0.51115203 | L151: =+VLOOKUP(E151,Material!$H$2:$M$17,6,FALSE)*G151*H151*(1+Material!$K$14) -> 6.5613333 | M151: =+Analisis!$J$5 -> T5.0 | N151: =+VLOOKUP(M151,Material!$A$3:$B$58,2,FALSE) -> 5000 | O151: ACERO A36 | P151: Cal 12 | Q151: =+IF(O151="ACERO A36",VLOOKUP(P151,'Velocidades Std 1500 w'!$B$2:$F$15,5,FALSE),IF(O151="INOXIDABLE",VLOOKUP(P151,'Velocidades Std 1500 w'!$B$17:$F$28,5,FALSE),IF(O151="ALUMINIO",VLOOKUP(P151,'Velocidades Std 1500 w'!$B$30:$F$38,5,FALSE)))) -> 4.3859649e-06 | R151: =+Q151*N151 -> 0.021929825 | S151: =+Q151*T151*3600 -> 7.9504674 | T151: =(+H151*2+G151*2+V151*1.5)*25.4*1.05 -> 503.5296 | U151: =+T151*R151 -> 11.042316 | V151: 4 | W151: =+IF(O151="ACERO A36",VLOOKUP(P151,'Tiempo Objeto'!$B$2:$C$12,2,FALSE),IF(O151="INOXIDABLE",VLOOKUP(P151,'Tiempo Objeto'!$B$14:$C$22,2,FALSE),IF(O151="ALUMINIO",VLOOKUP(P151,'Tiempo Objeto'!$B$24:$C$32,2,FALSE)))) -> 1.84 | X151: =+W151*V151 -> 7.36 | Y151: =+X151*N151/3600 -> 10.222222 | Z151: 0 | AA151: =30*Z151+Z151*$C151*1.5 -> 0 | AB151: =+Z151*Analisis!$J$6 -> 0 | AC151: 0 | AD151: =30*AC151+AC151*$C151*1.5 -> 0 | AE151: =+AD151*Analisis!$J$7 -> 0 | AF151: =+L151+U151+Y151+AB151+AE151 -> 27.825871 | AG151: =+AF151/(1-Analisis!$E$9) -> 34.782339 | AH151: =+AG151*C151 -> 0
B152: 11-A-6030-04 | C152: =IFERROR(VLOOKUP(B152,'REQ GALV'!A:B,2,0),0) -> 0 | D152: =+AG152 -> 28.362116 | E152: 12ga | F152: DECAPADO | G152: 2 | H152: 2.5 | I152: 0.105 | J152: 28.24 | K152: =+L152*2.2/J152 -> 0.28781083 | L152: =+VLOOKUP(E152,Material!$H$2:$M$17,6,FALSE)*G152*H152*(1+Material!$K$14) -> 3.6944444 | M152: =+Analisis!$J$5 -> T5.0 | N152: =+VLOOKUP(M152,Material!$A$3:$B$58,2,FALSE) -> 5000 | O152: ACERO A36 | P152: Cal 12 | Q152: =+IF(O152="ACERO A36",VLOOKUP(P152,'Velocidades Std 1500 w'!$B$2:$F$15,5,FALSE),IF(O152="INOXIDABLE",VLOOKUP(P152,'Velocidades Std 1500 w'!$B$17:$F$28,5,FALSE),IF(O152="ALUMINIO",VLOOKUP(P152,'Velocidades Std 1500 w'!$B$30:$F$38,5,FALSE)))) -> 4.3859649e-06 | R152: =+Q152*N152 -> 0.021929825 | S152: =+Q152*T152*3600 -> 6.3165789 | T152: =(+H152*2+G152*2+V152*1.5)*25.4*1.05 -> 400.05 | U152: =+T152*R152 -> 8.7730263 | V152: 4 | W152: =+IF(O152="ACERO A36",VLOOKUP(P152,'Tiempo Objeto'!$B$2:$C$12,2,FALSE),IF(O152="INOXIDABLE",VLOOKUP(P152,'Tiempo Objeto'!$B$14:$C$22,2,FALSE),IF(O152="ALUMINIO",VLOOKUP(P152,'Tiempo Objeto'!$B$24:$C$32,2,FALSE)))) -> 1.84 | X152: =+W152*V152 -> 7.36 | Y152: =+X152*N152/3600 -> 10.222222 | Z152: 0 | AA152: =30*Z152+Z152*$C152*1.5 -> 0 | AB152: =+Z152*Analisis!$J$6 -> 0 | AC152: 0 | AD152: =30*AC152+AC152*$C152*1.5 -> 0 | AE152: =+AD152*Analisis!$J$7 -> 0 | AF152: =+L152+U152+Y152+AB152+AE152 -> 22.689693 | AG152: =+AF152/(1-Analisis!$E$9) -> 28.362116 | AH152: =+AG152*C152 -> 0
